Workbook

Sheet Дэшборд
A1: ЦЕХ ПОЛУФАБРИКАТОВ — ДЭШБОРД
A2: Операционный уровень · 36 месяцев · выручка из объёмов и цен, себестоимость из рецептуры и штатного расписания
A4: Выручка за 3 года | C4: EBITDA за 3 года | E4: Рентабельность по EBITDA, год 3 | G4: Чистая прибыль, год 3 | I4: Минимальный остаток | K4: Остаток на конец
A5: =Модель!AL13 | C5: =Модель!AL33 | E5: =Сводка!D9/Сводка!D5 | G5: =Сводка!D13 | I5: =Сводка!B21 | K5: =Сводка!B22
A58: Пример из витрины. Все цифры условные и не относятся к какому-либо действующему бизнесу.

Sheet Сводка
A1: ЦЕХ ПОЛУФАБРИКАТОВ — СВОДКА
A2: Итоги по годам и контрольные показатели
A4: ПОКАЗАТЕЛЬ | B4: Год 1 | C4: Год 2 | D4: Год 3
A5: Выручка | B5: =SUM(Модель!B13:M13) | C5: =SUM(Модель!N13:Y13) | D5: =SUM(Модель!Z13:AK13)
A6: Переменные затраты | B6: =SUM(Модель!B20:M20) | C6: =SUM(Модель!N20:Y20) | D6: =SUM(Модель!Z20:AK20)
A7: Маржинальная прибыль | B7: =SUM(Модель!B21:M21) | C7: =SUM(Модель!N21:Y21) | D7: =SUM(Модель!Z21:AK21)
A8: Постоянные расходы | B8: =SUM(Модель!B32:M32) | C8: =SUM(Модель!N32:Y32) | D8: =SUM(Модель!Z32:AK32)
A9: EBITDA | B9: =SUM(Модель!B33:M33) | C9: =SUM(Модель!N33:Y33) | D9: =SUM(Модель!Z33:AK33)
A10: Амортизация | B10: =SUM(Модель!B36:M36) | C10: =SUM(Модель!N36:Y36) | D10: =SUM(Модель!Z36:AK36)
A11: Проценты по кредиту | B11: =SUM(Модель!B37:M37) | C11: =SUM(Модель!N37:Y37) | D11: =SUM(Модель!Z37:AK37)
A12: Корпоративный подоходный налог | B12: =SUM(Модель!B39:M39) | C12: =SUM(Модель!N39:Y39) | D12: =SUM(Модель!Z39:AK39)
A13: Чистая прибыль | B13: =SUM(Модель!B40:M40) | C13: =SUM(Модель!N40:Y40) | D13: =SUM(Модель!Z40:AK40)
A15: КОНТРОЛЬНЫЕ ПОКАЗАТЕЛИ
A16: Рентабельность по EBITDA, % | B16: =IF(B5=0,0,B9/B5) | C16: =IF(B5=0,0,C9/C5) | D16: =IF(B5=0,0,D9/D5)
A17: Рентабельность по чистой прибыли, % | B17: =IF(B5=0,0,B13/B5) | C17: =IF(C5=0,0,C13/C5) | D17: =IF(D5=0,0,D13/D5)
A18: Точка безубыточности, выручка в год | B18: =IF(B7=0,0,-B8/(B7/B5)) | C18: =IF(C7=0,0,-C8/(C7/C5)) | D18: =IF(D7=0,0,-D8/(D7/D5))
A19: Запас прочности, % | B19: =IF(B5=0,0,(B5-B18)/B5) | C19: =IF(C5=0,0,(C5-C18)/C5) | D19: =IF(D5=0,0,(D5-D18)/D5)
A21: Минимальный остаток на счёте за 3 года, ₸ | B21: =MIN(Модель!B55:Модель!AK55)
A22: Остаток на счёте на конец 3 года, ₸ | B22: =Модель!AK55
A23: Первый месяц с положительной EBITDA | B23: =IF(SUMPRODUCT(--(Модель!B33:AK33<=0))=36,"не достигнут","М "&(SUMPRODUCT(--(Модель!B33:AK33<=0))+1))
A24: Накопленная чистая прибыль за 3 года, ₸ | B24: =Модель!AL40
A26: Пример из витрины. Все цифры условные и не относятся к какому-либо действующему бизнесу.

Sheet Вводные
A1: ЦЕХ ПОЛУФАБРИКАТОВ — ВВОДНЫЕ
A2: Операционный уровень · все параметры модели собраны здесь · данные синтетические
A4: ПРОДУКТОВАЯ ЛИНЕЙКА
A5: Продукт | B5: Цена, ₸/кг | C5: Объём, кг/мес | D5: Сырьё, ₸/кг | E5: Упаковка, ₸/кг | F5: Прирост объёма, %/мес
A6: Пельмени | B6: 2450 | C6: 9000 | D6: 1650 | E6: 85 | F6: 0.025
A7: Котлеты | B7: 2150 | C7: 5500 | D7: 1450 | E7: 85 | F7: 0.02
A8: Вареники | B8: 1750 | C8: 3500 | D8: 1150 | E8: 85 | F8: 0.03
A10: ПРОИЗВОДСТВО
A11: Технологические потери, % от сырья | B11: 0.03 | C11: брак, зачистка, усушка
A12: Логистика и доставка, ₸/кг | B12: 45 | C12: переменная на объём
A13: Маркетинг и продвижение, % от выручки | B13: 0.02
A15: ШТАТНОЕ РАСПИСАНИЕ · оклады на руки
A16: Должность | B16: Человек | C16: Оклад, ₸/мес | D16: Фонд, ₸/мес
A17: Технолог | B17: 1 | C17: 450000 | D17: =B17*C17 | E17: производство
A18: Мастер смены | B18: 2 | C18: 320000 | D18: =B18*C18 | E18: производство
A19: Рабочий цеха | B19: 8 | C19: 230000 | D19: =B19*C19 | E19: производство
A20: Кладовщик | B20: 1 | C20: 220000 | D20: =B20*C20 | E20: производство
A21: Водитель-экспедитор | B21: 2 | C21: 250000 | D21: =B21*C21 | E21: производство
A22: Директор | B22: 1 | C22: 700000 | D22: =B22*C22 | E22: административный
A23: Бухгалтер | B23: 1 | C23: 350000 | D23: =B23*C23 | E23: административный
A24: Менеджер по продажам | B24: 2 | C24: 300000 | D24: =B24*C24 | E24: административный
A25: Фонд производственного персонала, на руки | D25: =D17+D18+D19+D20+D21
A26: Фонд административного персонала, на руки | D26: =D22+D23+D24
A27: Налоги и отчисления с ФОТ, % к сумме на руки | B27: 0.27 | C27: работодатель сверх окладов
A28: Индексация окладов, % в год | B28: 0.08
A30: ПОСТОЯННЫЕ РАСХОДЫ, ₸ в месяц
A31: Аренда цеха и склада | B31: 1400000
A32: Коммунальные услуги | B32: 380000
A33: Обслуживание оборудования | B33: 150000
A34: Связь, ПО, бухгалтерское обслуживание | B34: 180000
A35: Прочие постоянные | B35: 200000
A37: ОБОРОТНЫЙ КАПИТАЛ И НАЛОГИ
A38: Доля выручки, оплачиваемая в том же месяце | B38: 0.55 | C38: остальное — в следующем
A39: Доля закупки сырья, оплачиваемая в том же месяце | B39: 0.7 | C39: остальное — в следующем
A40: Запас сырья на складе, дней | B40: 20 | C40: вложение в оборотный капитал в мес. 1
A41: Ставка НДС | B41: 0.16 | C41: к уплате с добавленной стоимости
A42: Ставка КПН | B42: 0.2 | C42: с прибыли
A44: ИНВЕСТИЦИИ И ФИНАНСИРОВАНИЕ
A45: Оборудование и запуск цеха, ₸ | B45: 68000000 | C45: месяц 1
A46: Срок амортизации, лет | B46: 7
...

Sheet Модель
A1: ЦЕХ ПОЛУФАБРИКАТОВ — МОДЕЛЬ
A2: 36 месяцев · выручка и себестоимость считаются из объёмов, рецептуры и штатного расписания
A4: СТАТЬЯ | B4: М1 | C4: М2 | D4: М3 | E4: М4 | F4: М5 | G4: М6 | H4: М7 | I4: М8 | J4: М9 | K4: М10 | L4: М11 | M4: М12 | N4: М13 | O4: М14 | P4: М15 | Q4: М16 | R4: М17 | S4: М18 | T4: М19 | U4: М20 | V4: М21 | W4: М22 | X4: М23 | Y4: М24 | Z4: М25 | AA4: М26 | AB4: М27 | AC4: М28 | AD4: М29 | AE4: М30 | AF4: М31 | AG4: М32 | AH4: М33 | AI4: М34 | AJ4: М35 | AK4: М36 | AL4: ИТОГО 3 года
A6: ВЫРУЧКА
A7: Объём: Пельмени, кг | B7: =Вводные!$C$6 | C7: =B7*(1+Вводные!$F$6) | D7: =C7*(1+Вводные!$F$6) | E7: =D7*(1+Вводные!$F$6) | F7: =E7*(1+Вводные!$F$6) | G7: =F7*(1+Вводные!$F$6) | H7: =G7*(1+Вводные!$F$6) | I7: =H7*(1+Вводные!$F$6) | J7: =I7*(1+Вводные!$F$6) | ... AK7: =AJ7*(1+Вводные!$F$6) | AL7: =SUM(B7:AK7)
A8: Выручка: Пельмени | B8: =B7*Вводные!$B$6 | C8: =C7*Вводные!$B$6 | D8: =D7*Вводные!$B$6 | E8: =E7*Вводные!$B$6 | F8: =F7*Вводные!$B$6 | G8: =G7*Вводные!$B$6 | H8: =H7*Вводные!$B$6 | I8: =I7*Вводные!$B$6 | ... AK8: =AK7*Вводные!$B$6 | AL8: =SUM(B8:AK8)
A9: Объём: Котлеты, кг | B9: =Вводные!$C$7 | C9: =B9*(1+Вводные!$F$7) | D9: =C9*(1+Вводные!$F$7) | E9: =D9*(1+Вводные!$F$7) | F9: =E9*(1+Вводные!$F$7) | G9: =F9*(1+Вводные!$F$7) | H9: =G9*(1+Вводные!$F$7) | I9: =H9*(1+Вводные!$F$7) | J9: =I9*(1+Вводные!$F$7) | ... AK9: =AJ9*(1+Вводные!$F$7) | AL9: =SUM(B9:AK9)
A10: Выручка: Котлеты | B10: =B9*Вводные!$B$7 | C10: =C9*Вводные!$B$7 | D10: =D9*Вводные!$B$7 | E10: =E9*Вводные!$B$7 | F10: =F9*Вводные!$B$7 | G10: =G9*Вводные!$B$7 | H10: =H9*Вводные!$B$7 | I10: =I9*Вводные!$B$7 | ... AK10: =AK9*Вводные!$B$7 | AL10: =SUM(B10:AK10)
A11: Объём: Вареники, кг | B11: =Вводные!$C$8 | C11: =B11*(1+Вводные!$F$8) | D11: =C11*(1+Вводные!$F$8) | E11: =D11*(1+Вводные!$F$8) | F11: =E11*(1+Вводные!$F$8) | G11: =F11*(1+Вводные!$F$8) | H11: =G11*(1+Вводные!$F$8) | I11: =H11*(1+Вводные!$F$8) | J11: =I11*(1+Вводные!$F$8) | ... AK11: =AJ11*(1+Вводные!$F$8) | AL11: =SUM(B11:AK11)
A12: Выручка: Вареники | B12: =B11*Вводные!$B$8 | C12: =C11*Вводные!$B$8 | D12: =D11*Вводные!$B$8 | E12: =E11*Вводные!$B$8 | F12: =F11*Вводные!$B$8 | G12: =G11*Вводные!$B$8 | H12: =H11*Вводные!$B$8 | I12: =I11*Вводные!$B$8 | ... AK12: =AK11*Вводные!$B$8 | AL12: =SUM(B12:AK12)
A13: ИТОГО ВЫРУЧКА | B13: =B8+B10+B12 | C13: =C8+C10+C12 | D13: =D8+D10+D12 | E13: =E8+E10+E12 | F13: =F8+F10+F12 | G13: =G8+G10+G12 | H13: =H8+H10+H12 | I13: =I8+I10+I12 | ... AK13: =AK8+AK10+AK12 | AL13: =SUM(B13:AK13)
A15: ПЕРЕМЕННЫЕ ЗАТРАТЫ
A16: Сырьё (по рецептуре, с учётом потерь) | B16: =-(B7*Вводные!$D$6+B9*Вводные!$D$7+B11*Вводные!$D$8)*(1+Вводные!$B$11) | C16: =-(C7*Вводные!$D$6+C9*Вводные!$D$7+C11*Вводные!$D$8)*(1+Вводные!$B$11) | D16: =-(D7*Вводные!$D$6+D9*Вводные!$D$7+D11*Вводные!$D$8)*(1+Вводные!$B$11) | E16: =-(E7*Вводные!$D$6+E9*Вводные!$D$7+E11*Вводные!$D$8)*(1+Вводные!$B$11) | F16: =-(F7*Вводные!$D$6+F9*Вводные!$D$7+F11*Вводные!$D$8)*(1+Вводные!$B$11) | G16: =-(G7*Вводные!$D$6+G9*Вводные!$D$7+G11*Вводные!$D$8)*(1+Вводные!$B$11) | H16: =-(H7*Вводные!$D$6+H9*Вводные!$D$7+H11*Вводные!$D$8)*(1+Вводные!$B$11) | I16: =-(I7*Вводные!$D$6+I9*Вводные!$D$7+I11*Вводные!$D$8)*(1+Вводные!$B$11) | ... AK16: =-(AK7*Вводные!$D$6+AK9*Вводные!$D$7+AK11*Вводные!$D$8)*(1+Вводные!$B$11) | AL16: =SUM(B16:AK16)
A17: Упаковка | B17: =-(B7*Вводные!$E$6+B9*Вводные!$E$7+B11*Вводные!$E$8) | C17: =-(C7*Вводные!$E$6+C9*Вводные!$E$7+C11*Вводные!$E$8) | D17: =-(D7*Вводные!$E$6+D9*Вводные!$E$7+D11*Вводные!$E$8) | E17: =-(E7*Вводные!$E$6+E9*Вводные!$E$7+E11*Вводные!$E$8) | F17: =-(F7*Вводные!$E$6+F9*Вводные!$E$7+F11*Вводные!$E$8) | G17: =-(G7*Вводные!$E$6+G9*Вводные!$E$7+G11*Вводные!$E$8) | H17: =-(H7*Вводные!$E$6+H9*Вводные!$E$7+H11*Вводные!$E$8) | I17: =-(I7*Вводные!$E$6+I9*Вводные!$E$7+I11*Вводные!$E$8) | ... AK17: =-(AK7*Вводные!$E$6+AK9*Вводные!$E$7+AK11*Вводные!$E$8) | AL17: =SUM(B17:AK17)
A18: Логистика и доставка | B18: =-(B7+B9+B11)*Вводные!$B$12 | C18: =-(C7+C9+C11)*Вводные!$B$12 | D18: =-(D7+D9+D11)*Вводные!$B$12 | E18: =-(E7+E9+E11)*Вводные!$B$12 | F18: =-(F7+F9+F11)*Вводные!$B$12 | G18: =-(G7+G9+G11)*Вводные!$B$12 | H18: =-(H7+H9+H11)*Вводные!$B$12 | I18: =-(I7+I9+I11)*Вводные!$B$12 | ... AK18: =-(AK7+AK9+AK11)*Вводные!$B$12 | AL18: =SUM(B18:AK18)
A19: Маркетинг | B19: =-B13*Вводные!$B$13 | C19: =-C13*Вводные!$B$13 | D19: =-D13*Вводные!$B$13 | E19: =-E13*Вводные!$B$13 | F19: =-F13*Вводные!$B$13 | G19: =-G13*Вводные!$B$13 | H19: =-H13*Вводные!$B$13 | I19: =-I13*Вводные!$B$13 | ... AK19: =-AK13*Вводные!$B$13 | AL19: =SUM(B19:AK19)
A20: Итого переменные затраты | B20: =SUM(B16:B19) | C20: =SUM(C16:C19) | D20: =SUM(D16:D19) | E20: =SUM(E16:E19) | F20: =SUM(F16:F19) | G20: =SUM(G16:G19) | H20: =SUM(H16:H19) | I20: =SUM(I16:I19) | ... AK20: =SUM(AK16:AK19) | AL20: =SUM(B20:AK20)
A21: МАРЖИНАЛЬНАЯ ПРИБЫЛЬ | B21: =B13+B20 | C21: =C13+C20 | D21: =D13+D20 | E21: =E13+E20 | F21: =F13+F20 | G21: =G13+G20 | H21: =H13+H20 | I21: =I13+I20 | ... AK21: =AK13+AK20 | AL21: =SUM(B21:AK21)
A22: Маржинальность, % | B22: =IF(B13=0,0,B21/B13) | C22: =IF(C13=0,0,C21/C13) | D22: =IF(D13=0,0,D21/D13) | E22: =IF(E13=0,0,E21/E13) | F22: =IF(F13=0,0,F21/F13) | G22: =IF(G13=0,0,G21/G13) | H22: =IF(H13=0,0,H21/H13) | I22: =IF(I13=0,0,I21/I13) | ... AK22: =IF(AK13=0,0,AK21/AK13)
A24: ПОСТОЯННЫЕ РАСХОДЫ
A25: Оплата труда: производство | B25: =-Вводные!$D$25*(1+Вводные!$B$27)*(1+Вводные!$B$28)^INT(0/12) | C25: =-Вводные!$D$25*(1+Вводные!$B$27)*(1+Вводные!$B$28)^INT(1/12) | D25: =-Вводные!$D$25*(1+Вводные!$B$27)*(1+Вводные!$B$28)^INT(2/12) | E25: =-Вводные!$D$25*(1+Вводные!$B$27)*(1+Вводные!$B$28)^INT(3/12) | F25: =-Вводные!$D$25*(1+Вводные!$B$27)*(1+Вводные!$B$28)^INT(4/12) | G25: =-Вводные!$D$25*(1+Вводные!$B$27)*(1+Вводные!$B$28)^INT(5/12) | H25: =-Вводные!$D$25*(1+Вводные!$B$27)*(1+Вводные!$B$28)^INT(6/12) | I25: =-Вводные!$D$25*(1+Вводные!$B$27)*(1+Вводные!$B$28)^INT(7/12) | J25: =-Вводные!$D$25*(1+Вводные!$B$27)*(1+Вводные!$B$28)^INT(8/12) | K25: =-Вводные!$D$25*(1+Вводные!$B$27)*(1+Вводные!$B$28)^INT(9/12) | L25: =-Вводные!$D$25*(1+Вводные!$B$27)*(1+Вводные!$B$28)^INT(10/12) | M25: =-Вводные!$D$25*(1+Вводные!$B$27)*(1+Вводные!$B$28)^INT(11/12) | N25: =-Вводные!$D$25*(1+Вводные!$B$27)*(1+Вводные!$B$28)^INT(12/12) | O25: =-Вводные!$D$25*(1+Вводные!$B$27)*(1+Вводные!$B$28)^INT(13/12) | P25: =-Вводные!$D$25*(1+Вводные!$B$27)*(1+Вводные!$B$28)^INT(14/12) | Q25: =-Вводные!$D$25*(1+Вводные!$B$27)*(1+Вводные!$B$28)^INT(15/12) | R25: =-Вводные!$D$25*(1+Вводные!$B$27)*(1+Вводные!$B$28)^INT(16/12) | S25: =-Вводные!$D$25*(1+Вводные!$B$27)*(1+Вводные!$B$28)^INT(17/12) | T25: =-Вводные!$D$25*(1+Вводные!$B$27)*(1+Вводные!$B$28)^INT(18/12) | U25: =-Вводные!$D$25*(1+Вводные!$B$27)*(1+Вводные!$B$28)^INT(19/12) | V25: =-Вводные!$D$25*(1+Вводные!$B$27)*(1+Вводные!$B$28)^INT(20/12) | W25: =-Вводные!$D$25*(1+Вводные!$B$27)*(1+Вводные!$B$28)^INT(21/12) | X25: =-Вводные!$D$25*(1+Вводные!$B$27)*(1+Вводные!$B$28)^INT(22/12) | Y25: =-Вводные!$D$25*(1+Вводные!$B$27)*(1+Вводные!$B$28)^INT(23/12) | Z25: =-Вводные!$D$25*(1+Вводные!$B$27)*(1+Вводные!$B$28)^INT(24/12) | AA25: =-Вводные!$D$25*(1+Вводные!$B$27)*(1+Вводные!$B$28)^INT(25/12) | AB25: =-Вводные!$D$25*(1+Вводные!$B$27)*(1+Вводные!$B$28)^INT(26/12) | AC25: =-Вводные!$D$25*(1+Вводные!$B$27)*(1+Вводные!$B$28)^INT(27/12) | AD25: =-Вводные!$D$25*(1+Вводные!$B$27)*(1+Вводные!$B$28)^INT(28/12) | AE25: =-Вводные!$D$25*(1+Вводные!$B$27)*(1+Вводные!$B$28)^INT(29/12) | AF25: =-Вводные!$D$25*(1+Вводные!$B$27)*(1+Вводные!$B$28)^INT(30/12) | AG25: =-Вводные!$D$25*(1+Вводные!$B$27)*(1+Вводные!$B$28)^INT(31/12) | AH25: =-Вводные!$D$25*(1+Вводные!$B$27)*(1+Вводные!$B$28)^INT(32/12) | AI25: =-Вводные!$D$25*(1+Вводные!$B$27)*(1+Вводные!$B$28)^INT(33/12) | AJ25: =-Вводные!$D$25*(1+Вводные!$B$27)*(1+Вводные!$B$28)^INT(34/12) | AK25: =-Вводные!$D$25*(1+Вводные!$B$27)*(1+Вводные!$B$28)^INT(35/12) | AL25: =SUM(B25:AK25)
A26: Оплата труда: администрация | B26: =-Вводные!$D$26*(1+Вводные!$B$27)*(1+Вводные!$B$28)^INT(0/12) | C26: =-Вводные!$D$26*(1+Вводные!$B$27)*(1+Вводные!$B$28)^INT(1/12) | D26: =-Вводные!$D$26*(1+Вводные!$B$27)*(1+Вводные!$B$28)^INT(2/12) | E26: =-Вводные!$D$26*(1+Вводные!$B$27)*(1+Вводные!$B$28)^INT(3/12) | F26: =-Вводные!$D$26*(1+Вводные!$B$27)*(1+Вводные!$B$28)^INT(4/12) | G26: =-Вводные!$D$26*(1+Вводные!$B$27)*(1+Вводные!$B$28)^INT(5/12) | H26: =-Вводные!$D$26*(1+Вводные!$B$27)*(1+Вводные!$B$28)^INT(6/12) | I26: =-Вводные!$D$26*(1+Вводные!$B$27)*(1+Вводные!$B$28)^INT(7/12) | J26: =-Вводные!$D$26*(1+Вводные!$B$27)*(1+Вводные!$B$28)^INT(8/12) | K26: =-Вводные!$D$26*(1+Вводные!$B$27)*(1+Вводные!$B$28)^INT(9/12) | L26: =-Вводные!$D$26*(1+Вводные!$B$27)*(1+Вводные!$B$28)^INT(10/12) | M26: =-Вводные!$D$26*(1+Вводные!$B$27)*(1+Вводные!$B$28)^INT(11/12) | N26: =-Вводные!$D$26*(1+Вводные!$B$27)*(1+Вводные!$B$28)^INT(12/12) | O26: =-Вводные!$D$26*(1+Вводные!$B$27)*(1+Вводные!$B$28)^INT(13/12) | P26: =-Вводные!$D$26*(1+Вводные!$B$27)*(1+Вводные!$B$28)^INT(14/12) | Q26: =-Вводные!$D$26*(1+Вводные!$B$27)*(1+Вводные!$B$28)^INT(15/12) | R26: =-Вводные!$D$26*(1+Вводные!$B$27)*(1+Вводные!$B$28)^INT(16/12) | S26: =-Вводные!$D$26*(1+Вводные!$B$27)*(1+Вводные!$B$28)^INT(17/12) | T26: =-Вводные!$D$26*(1+Вводные!$B$27)*(1+Вводные!$B$28)^INT(18/12) | U26: =-Вводные!$D$26*(1+Вводные!$B$27)*(1+Вводные!$B$28)^INT(19/12) | V26: =-Вводные!$D$26*(1+Вводные!$B$27)*(1+Вводные!$B$28)^INT(20/12) | W26: =-Вводные!$D$26*(1+Вводные!$B$27)*(1+Вводные!$B$28)^INT(21/12) | X26: =-Вводные!$D$26*(1+Вводные!$B$27)*(1+Вводные!$B$28)^INT(22/12) | Y26: =-Вводные!$D$26*(1+Вводные!$B$27)*(1+Вводные!$B$28)^INT(23/12) | Z26: =-Вводные!$D$26*(1+Вводные!$B$27)*(1+Вводные!$B$28)^INT(24/12) | AA26: =-Вводные!$D$26*(1+Вводные!$B$27)*(1+Вводные!$B$28)^INT(25/12) | AB26: =-Вводные!$D$26*(1+Вводные!$B$27)*(1+Вводные!$B$28)^INT(26/12) | AC26: =-Вводные!$D$26*(1+Вводные!$B$27)*(1+Вводные!$B$28)^INT(27/12) | AD26: =-Вводные!$D$26*(1+Вводные!$B$27)*(1+Вводные!$B$28)^INT(28/12) | AE26: =-Вводные!$D$26*(1+Вводные!$B$27)*(1+Вводные!$B$28)^INT(29/12) | AF26: =-Вводные!$D$26*(1+Вводные!$B$27)*(1+Вводные!$B$28)^INT(30/12) | AG26: =-Вводные!$D$26*(1+Вводные!$B$27)*(1+Вводные!$B$28)^INT(31/12) | AH26: =-Вводные!$D$26*(1+Вводные!$B$27)*(1+Вводные!$B$28)^INT(32/12) | AI26: =-Вводные!$D$26*(1+Вводные!$B$27)*(1+Вводные!$B$28)^INT(33/12) | AJ26: =-Вводные!$D$26*(1+Вводные!$B$27)*(1+Вводные!$B$28)^INT(34/12) | AK26: =-Вводные!$D$26*(1+Вводные!$B$27)*(1+Вводные!$B$28)^INT(35/12) | AL26: =SUM(B26:AK26)
A27: Аренда цеха и склада | B27: =-Вводные!$B$31 | C27: =-Вводные!$B$31 | D27: =-Вводные!$B$31 | E27: =-Вводные!$B$31 | F27: =-Вводные!$B$31 | G27: =-Вводные!$B$31 | H27: =-Вводные!$B$31 | I27: =-Вводные!$B$31 | ... AK27: =-Вводные!$B$31 | AL27: =SUM(B27:AK27)
A28: Коммунальные услуги | B28: =-Вводные!$B$32 | C28: =-Вводные!$B$32 | D28: =-Вводные!$B$32 | E28: =-Вводные!$B$32 | F28: =-Вводные!$B$32 | G28: =-Вводные!$B$32 | H28: =-Вводные!$B$32 | I28: =-Вводные!$B$32 | ... AK28: =-Вводные!$B$32 | AL28: =SUM(B28:AK28)
A29: Обслуживание оборудования | B29: =-Вводные!$B$33 | C29: =-Вводные!$B$33 | D29: =-Вводные!$B$33 | E29: =-Вводные!$B$33 | F29: =-Вводные!$B$33 | G29: =-Вводные!$B$33 | H29: =-Вводные!$B$33 | I29: =-Вводные!$B$33 | ... AK29: =-Вводные!$B$33 | AL29: =SUM(B29:AK29)
A30: Связь, ПО, бухгалтерское обслуживание | B30: =-Вводные!$B$34 | C30: =-Вводные!$B$34 | D30: =-Вводные!$B$34 | E30: =-Вводные!$B$34 | F30: =-Вводные!$B$34 | G30: =-Вводные!$B$34 | H30: =-Вводные!$B$34 | I30: =-Вводные!$B$34 | ... AK30: =-Вводные!$B$34 | AL30: =SUM(B30:AK30)
A31: Прочие постоянные | B31: =-Вводные!$B$35 | C31: =-Вводные!$B$35 | D31: =-Вводные!$B$35 | E31: =-Вводные!$B$35 | F31: =-Вводные!$B$35 | G31: =-Вводные!$B$35 | H31: =-Вводные!$B$35 | I31: =-Вводные!$B$35 | ... AK31: =-Вводные!$B$35 | AL31: =SUM(B31:AK31)
A32: Итого постоянные расходы | B32: =SUM(B25:B31) | C32: =SUM(C25:C31) | D32: =SUM(D25:D31) | E32: =SUM(E25:E31) | F32: =SUM(F25:F31) | G32: =SUM(G25:G31) | H32: =SUM(H25:H31) | I32: =SUM(I25:I31) | ... AK32: =SUM(AK25:AK31) | AL32: =SUM(B32:AK32)
A33: EBITDA | B33: =B21+B32 | C33: =C21+C32 | D33: =D21+D32 | E33: =E21+E32 | F33: =F21+F32 | G33: =G21+G32 | H33: =H21+H32 | I33: =I21+I32 | ... AK33: =AK21+AK32 | AL33: =SUM(B33:AK33)
A35: ПРИБЫЛЬ
A36: Амортизация | B36: =-Вводные!$B$45/Вводные!$B$46/12 | C36: =-Вводные!$B$45/Вводные!$B$46/12 | D36: =-Вводные!$B$45/Вводные!$B$46/12 | E36: =-Вводные!$B$45/Вводные!$B$46/12 | F36: =-Вводные!$B$45/Вводные!$B$46/12 | G36: =-Вводные!$B$45/Вводные!$B$46/12 | H36: =-Вводные!$B$45/Вводные!$B$46/12 | I36: =-Вводные!$B$45/Вводные!$B$46/12 | ... AK36: =-Вводные!$B$45/Вводные!$B$46/12 | AL36: =SUM(B36:AK36)
A37: Проценты по кредиту | B37: =-Вводные!$B$48*Вводные!$B$49/12 | C37: =-B56*Вводные!$B$49/12 | D37: =-C56*Вводные!$B$49/12 | E37: =-D56*Вводные!$B$49/12 | F37: =-E56*Вводные!$B$49/12 | G37: =-F56*Вводные!$B$49/12 | H37: =-G56*Вводные!$B$49/12 | I37: =-H56*Вводные!$B$49/12 | J37: =-I56*Вводные!$B$49/12 | ... AK37: =-AJ56*Вводные!$B$49/12 | AL37: =SUM(B37:AK37)
A38: Прибыль до налога | B38: =B33+B36+B37 | C38: =C33+C36+C37 | D38: =D33+D36+D37 | E38: =E33+E36+E37 | F38: =F33+F36+F37 | G38: =G33+G36+G37 | H38: =H33+H36+H37 | I38: =I33+I36+I37 | ... AK38: =AK33+AK36+AK37 | AL38: =SUM(B38:AK38)
A39: Корпоративный подоходный налог | B39: =-MAX(0,B38)*Вводные!$B$42 | C39: =-MAX(0,C38)*Вводные!$B$42 | D39: =-MAX(0,D38)*Вводные!$B$42 | E39: =-MAX(0,E38)*Вводные!$B$42 | F39: =-MAX(0,F38)*Вводные!$B$42 | G39: =-MAX(0,G38)*Вводные!$B$42 | H39: =-MAX(0,H38)*Вводные!$B$42 | I39: =-MAX(0,I38)*Вводные!$B$42 | ... AK39: =-MAX(0,AK38)*Вводные!$B$42 | AL39: =SUM(B39:AK39)
A40: ЧИСТАЯ ПРИБЫЛЬ | B40: =B38+B39 | C40: =C38+C39 | D40: =D38+D39 | E40: =E38+E39 | F40: =F38+F39 | G40: =G38+G39 | H40: =H38+H39 | I40: =I38+I39 | ... AK40: =AK38+AK39 | AL40: =SUM(B40:AK40)
A42: ДВИЖЕНИЕ ДЕНЕЖНЫХ СРЕДСТВ
A43: Остаток на начало месяца | B43: =0 | C43: =B55 | D43: =C55 | E43: =D55 | F43: =E55 | G43: =F55 | H43: =G55 | I43: =H55 | J43: =I55 | ... AK43: =AJ55
A44: Поступления от покупателей (с НДС) | B44: =B13*Вводные!$B$38*(1+Вводные!$B$41) | C44: =(C13*Вводные!$B$38+B13*(1-Вводные!$B$38))*(1+Вводные!$B$41) | D44: =(D13*Вводные!$B$38+C13*(1-Вводные!$B$38))*(1+Вводные!$B$41) | E44: =(E13*Вводные!$B$38+D13*(1-Вводные!$B$38))*(1+Вводные!$B$41) | F44: =(F13*Вводные!$B$38+E13*(1-Вводные!$B$38))*(1+Вводные!$B$41) | G44: =(G13*Вводные!$B$38+F13*(1-Вводные!$B$38))*(1+Вводные!$B$41) | H44: =(H13*Вводные!$B$38+G13*(1-Вводные!$B$38))*(1+Вводные!$B$41) | I44: =(I13*Вводные!$B$38+H13*(1-Вводные!$B$38))*(1+Вводные!$B$41) | J44: =(J13*Вводные!$B$38+I13*(1-Вводные!$B$38))*(1+Вводные!$B$41) | ... AK44: =(AK13*Вводные!$B$38+AJ13*(1-Вводные!$B$38))*(1+Вводные!$B$41) | AL44: =SUM(B44:AK44)
A45: Оплата сырья и упаковки (с НДС) | B45: =(B16+B17)*Вводные!$B$39*(1+Вводные!$B$41) | C45: =((C16+C17)*Вводные!$B$39+(B16+B17)*(1-Вводные!$B$39))*(1+Вводные!$B$41) | D45: =((D16+D17)*Вводные!$B$39+(C16+C17)*(1-Вводные!$B$39))*(1+Вводные!$B$41) | E45: =((E16+E17)*Вводные!$B$39+(D16+D17)*(1-Вводные!$B$39))*(1+Вводные!$B$41) | F45: =((F16+F17)*Вводные!$B$39+(E16+E17)*(1-Вводные!$B$39))*(1+Вводные!$B$41) | G45: =((G16+G17)*Вводные!$B$39+(F16+F17)*(1-Вводные!$B$39))*(1+Вводные!$B$41) | H45: =((H16+H17)*Вводные!$B$39+(G16+G17)*(1-Вводные!$B$39))*(1+Вводные!$B$41) | I45: =((I16+I17)*Вводные!$B$39+(H16+H17)*(1-Вводные!$B$39))*(1+Вводные!$B$41) | J45: =((J16+J17)*Вводные!$B$39+(I16+I17)*(1-Вводные!$B$39))*(1+Вводные!$B$41) | ... AK45: =((AK16+AK17)*Вводные!$B$39+(AJ16+AJ17)*(1-Вводные!$B$39))*(1+Вводные!$B$41) | AL45: =SUM(B45:AK45)
A46: Формирование запаса сырья | B46: =(B16+B17)*Вводные!$B$40/30*(1+Вводные!$B$41) | C46: =0 | D46: =0 | E46: =0 | F46: =0 | G46: =0 | H46: =0 | I46: =0 | J46: =0 | ... AK46: =0 | AL46: =SUM(B46:AK46)
...

Sheet _График
B1: М1 | C1: М2 | D1: М3 | E1: М4 | F1: М5 | G1: М6 | H1: М7 | I1: М8 | J1: М9 | K1: М10 | L1: М11 | M1: М12 | N1: М13 | O1: М14 | P1: М15 | Q1: М16 | R1: М17 | S1: М18 | T1: М19 | U1: М20 | V1: М21 | W1: М22 | X1: М23 | Y1: М24 | Z1: М25 | AA1: М26 | AB1: М27 | AC1: М28 | AD1: М29 | AE1: М30 | AF1: М31 | AG1: М32 | AH1: М33 | AI1: М34 | AJ1: М35 | AK1: М36
A2: Выручка | B2: =Модель!B13 | C2: =Модель!C13 | D2: =Модель!D13 | E2: =Модель!E13 | F2: =Модель!F13 | G2: =Модель!G13 | H2: =Модель!H13 | I2: =Модель!I13 | ... AK2: =Модель!AK13
A3: EBITDA | B3: =Модель!B33 | C3: =Модель!C33 | D3: =Модель!D33 | E3: =Модель!E33 | F3: =Модель!F33 | G3: =Модель!G33 | H3: =Модель!H33 | I3: =Модель!I33 | ... AK3: =Модель!AK33
A4: Остаток на счёте | B4: =Модель!B55 | C4: =Модель!C55 | D4: =Модель!D55 | E4: =Модель!E55 | F4: =Модель!F55 | G4: =Модель!G55 | H4: =Модель!H55 | I4: =Модель!I55 | ... AK4: =Модель!AK55
A5: Маржинальная прибыль | B5: =Модель!B21 | C5: =Модель!C21 | D5: =Модель!D21 | E5: =Модель!E21 | F5: =Модель!F21 | G5: =Модель!G21 | H5: =Модель!H21 | I5: =Модель!I21 | ... AK5: =Модель!AK21
A6: Пельмени | B6: =Модель!B7 | C6: =Модель!C7 | D6: =Модель!D7 | E6: =Модель!E7 | F6: =Модель!F7 | G6: =Модель!G7 | H6: =Модель!H7 | I6: =Модель!I7 | ... AK6: =Модель!AK7
A7: Котлеты | B7: =Модель!B9 | C7: =Модель!C9 | D7: =Модель!D9 | E7: =Модель!E9 | F7: =Модель!F9 | G7: =Модель!G9 | H7: =Модель!H9 | I7: =Модель!I9 | ... AK7: =Модель!AK9
A8: Вареники | B8: =Модель!B11 | C8: =Модель!C11 | D8: =Модель!D11 | E8: =Модель!E11 | F8: =Модель!F11 | G8: =Модель!G11 | H8: =Модель!H11 | I8: =Модель!I11 | ... AK8: =Модель!AK11
A10: Сырьё | B10: =ABS(Модель!AL16)
A11: Упаковка | B11: =ABS(Модель!AL17)
A12: Логистика | B12: =ABS(Модель!AL18)
A13: Маркетинг | B13: =ABS(Модель!AL19)
A14: Оплата труда: производство | B14: =ABS(Модель!AL25)
A15: Оплата труда: администрация | B15: =ABS(Модель!AL26)
A16: Аренда | B16: =ABS(Модель!AL27)
A17: Коммунальные | B17: =ABS(Модель!AL28)
A18: Обслуживание оборудования | B18: =ABS(Модель!AL29)
A19: Связь и обслуживание | B19: =ABS(Модель!AL30)
A20: Прочие | B20: =ABS(Модель!AL31)
