Workbook

Sheet Дэшборд
A1: БАЗА ОТДЫХА НА 12 ГОСТЕВЫХ ДОМОВ
A2: Инвестиционный дэшборд · 12 домов · строительство 24 мес. · горизонт 10 лет
A4: Инвестиции | C4: NPV проекта | E4: IRR проекта | G4: IRR собственника | I4: Окупаемость, лет | K4: Минимальный DSCR
A5: =Вводные!$B$11 | C5: =Модель!L44 | E5: =IRR(Модель!B40:L40) | G5: =IRR(Модель!B41:L41) | I5: =IF(SUMPRODUCT(--(Модель!B44:L44<0))=11,"свыше 10 лет",SUMPRODUCT(--(Модель!B44:L44<0))) | K5: =MIN(Модель!D36:L36)
A7: Ставка дисконтирования — WACC, считается из структуры финансирования на листе «Вводные». Ковенант банка по DSCR задан там же.
A73: Пример из витрины. Все цифры условные и не относятся к какому-либо действующему проекту.

Sheet Вводные
A1: БАЗА ОТДЫХА НА 12 ГОСТЕВЫХ ДОМОВ — ВВОДНЫЕ
A2: Проектный уровень · строительство 24 месяца, эксплуатация 9 лет · данные синтетические
A4: ИНВЕСТИЦИИ, ₸
A5: Земельный участок | B5: 25000000 | C5: месяц 1
A6: Проектирование и согласования | B6: 15000000 | C6: месяцы 1–4
A7: Стоимость одного гостевого дома | B7: 15000000 | C7: кривая освоения — лист «Инвестфаза»
A8: Количество домов | B8: 12
A9: Инженерные сети и благоустройство | B9: 60000000 | C9: месяцы 5–20
A10: Мебель, оборудование, текстиль | B10: 36000000 | C10: месяцы 19–24
A11: ИТОГО инвестиции | B11: =B5+B6+B7*B8+B9+B10
A13: ЭКСПЛУАТАЦИЯ
A14: Средний тариф за ночь, ₸ | B14: 55000
A15: Индексация тарифа, % в год | B15: 0.07
A16: Загрузка в первый год эксплуатации, % | B16: 0.38 | C16: год 2
A17: Загрузка на выходе, % | B17: 0.55 | C17: достигается за 3 года
A18: Лет до выхода на целевую загрузку | B18: 3
A19: Дополнительные доходы, % к размещению | B19: 0.3 | C19: питание, баня, мероприятия
A21: ОПЕРАЦИОННЫЕ РАСХОДЫ
A22: Переменные расходы, % от выручки | B22: 0.22 | C22: уборка, бельё, продукты, расходники
A23: Фонд оплаты труда на руки, ₸ в год | B23: 28000000
A24: Налоги и отчисления с ФОТ, % | B24: 0.27
A25: Коммунальные услуги, ₸ в год | B25: 11000000
A26: Текущий ремонт и содержание, ₸ в год | B26: 7000000
A27: Маркетинг и каналы продаж, % от выручки | B27: 0.08 | C27: агрегаторы, реклама
A28: Управление и прочие, ₸ в год | B28: 8000000
A29: Индексация расходов, % в год | B29: 0.06
A31: ФИНАНСИРОВАНИЕ, НАЛОГИ, СТОИМОСТЬ КАПИТАЛА
A32: Собственные средства, ₸ | B32: 216000000
A33: Кредит, ₸ | B33: 100000000 | C33: транши по мере освоения
A34: Ставка по кредиту, % годовых | B34: 0.18
A35: Срок кредита, лет | B35: 10
A36: Отсрочка погашения тела, лет | B36: 3 | C36: на время строительства
A37: Требуемая доходность собственника, % | B37: 0.18 | C37: альтернатива вложению в проект
A38: Срок амортизации, лет | B38: 15
A39: Ставка КПН | B39: 0.2
A40: Терминальный множитель к EBITDA года 10 | B40: 5 | C40: оценка объекта при выходе
A41: Ковенант банка: минимальный DSCR | B41: 1.25 | C41: обслуживание долга
A42: Доля долга в финансировании | B42: =B33/(B33+B32)
A43: Средневзвешенная стоимость капитала (WACC) | B43: =B33/(B33+B32)*B34*(1-B39)+B32/(B33+B32)*B37 | C43: ставка дисконтирования проекта — считается, не задаётся вручную
A45: Пример из витрины. Все цифры условные и не относятся к какому-либо действующему проекту.

Sheet Инвестфаза
A1: ИНВЕСТИЦИОННАЯ ФАЗА — 24 МЕСЯЦА
A2: Освоение по статьям и месяцам · транши кредита по факту освоения · процент готовности
A4: СТАТЬЯ | B4: М1 | C4: М2 | D4: М3 | E4: М4 | F4: М5 | G4: М6 | H4: М7 | I4: М8 | J4: М9 | K4: М10 | L4: М11 | M4: М12 | N4: М13 | O4: М14 | P4: М15 | Q4: М16 | R4: М17 | S4: М18 | T4: М19 | U4: М20 | V4: М21 | W4: М22 | X4: М23 | Y4: М24 | Z4: ИТОГО
A6: КРИВАЯ ОСВОЕНИЯ СМР
A7: Вес месяца в освоении СМР, % | B7: =0/94 | C7: =0/94 | D7: =0/94 | E7: =0/94 | F7: =2/94 | G7: =3/94 | H7: =5/94 | I7: =7/94 | J7: =9/94 | K7: =10/94 | L7: =11/94 | M7: =11/94 | N7: =10/94 | O7: =9/94 | P7: =7/94 | Q7: =5/94 | R7: =3/94 | S7: =2/94 | T7: =0/94 | U7: =0/94 | V7: =0/94 | W7: =0/94 | X7: =0/94 | Y7: =0/94 | Z7: =SUM(B7:Y7)
A8: ОСВОЕНИЕ ПО СТАТЬЯМ
A9: Земельный участок | B9: =Вводные!$B$5 | C9: =0 | D9: =0 | E9: =0 | F9: =0 | G9: =0 | H9: =0 | I9: =0 | J9: =0 | ... Y9: =0 | Z9: =SUM(B9:Y9)
A10: Проектирование и согласования | B10: =Вводные!$B$6/4 | C10: =Вводные!$B$6/4 | D10: =Вводные!$B$6/4 | E10: =Вводные!$B$6/4 | F10: =0 | G10: =0 | H10: =0 | I10: =0 | J10: =0 | K10: =0 | L10: =0 | M10: =0 | ... Y10: =0 | Z10: =SUM(B10:Y10)
A11: Строительство домов | B11: =Вводные!$B$7*Вводные!$B$8*B7 | C11: =Вводные!$B$7*Вводные!$B$8*C7 | D11: =Вводные!$B$7*Вводные!$B$8*D7 | E11: =Вводные!$B$7*Вводные!$B$8*E7 | F11: =Вводные!$B$7*Вводные!$B$8*F7 | G11: =Вводные!$B$7*Вводные!$B$8*G7 | H11: =Вводные!$B$7*Вводные!$B$8*H7 | I11: =Вводные!$B$7*Вводные!$B$8*I7 | ... Y11: =Вводные!$B$7*Вводные!$B$8*Y7 | Z11: =SUM(B11:Y11)
A12: Инженерные сети и благоустройство | B12: =0 | C12: =0 | D12: =0 | E12: =0 | F12: =Вводные!$B$9/16 | G12: =Вводные!$B$9/16 | H12: =Вводные!$B$9/16 | I12: =Вводные!$B$9/16 | J12: =Вводные!$B$9/16 | K12: =Вводные!$B$9/16 | L12: =Вводные!$B$9/16 | M12: =Вводные!$B$9/16 | ... U12: =Вводные!$B$9/16 | V12: =0 | W12: =0 | X12: =0 | Y12: =0 | Z12: =SUM(B12:Y12)
A13: Мебель, оборудование, текстиль | B13: =0 | C13: =0 | D13: =0 | E13: =0 | F13: =0 | G13: =0 | H13: =0 | I13: =0 | ... S13: =0 | T13: =Вводные!$B$10/6 | U13: =Вводные!$B$10/6 | V13: =Вводные!$B$10/6 | W13: =Вводные!$B$10/6 | X13: =Вводные!$B$10/6 | Y13: =Вводные!$B$10/6 | Z13: =SUM(B13:Y13)
A14: ИТОГО ОСВОЕНИЕ ЗА МЕСЯЦ | B14: =SUM(B9:B13) | C14: =SUM(C9:C13) | D14: =SUM(D9:D13) | E14: =SUM(E9:E13) | F14: =SUM(F9:F13) | G14: =SUM(G9:G13) | H14: =SUM(H9:H13) | I14: =SUM(I9:I13) | ... Y14: =SUM(Y9:Y13) | Z14: =SUM(B14:Y14)
A15: Накопленное освоение | B15: =B14 | C15: =B15+C14 | D15: =C15+D14 | E15: =D15+E14 | F15: =E15+F14 | G15: =F15+G14 | H15: =G15+H14 | I15: =H15+I14 | J15: =I15+J14 | ... Y15: =X15+Y14
A16: Готовность объекта, % | B16: =B15/Вводные!$B$11 | C16: =C15/Вводные!$B$11 | D16: =D15/Вводные!$B$11 | E16: =E15/Вводные!$B$11 | F16: =F15/Вводные!$B$11 | G16: =G15/Вводные!$B$11 | H16: =H15/Вводные!$B$11 | I16: =I15/Вводные!$B$11 | ... Y16: =Y15/Вводные!$B$11
A18: ФИНАНСИРОВАНИЕ ОСВОЕНИЯ
A19: Собственные средства | B19: =MIN(B14,Вводные!$B$32) | C19: =MIN(C14,MAX(0,Вводные!$B$32-B21)) | D19: =MIN(D14,MAX(0,Вводные!$B$32-C21)) | E19: =MIN(E14,MAX(0,Вводные!$B$32-D21)) | F19: =MIN(F14,MAX(0,Вводные!$B$32-E21)) | G19: =MIN(G14,MAX(0,Вводные!$B$32-F21)) | H19: =MIN(H14,MAX(0,Вводные!$B$32-G21)) | I19: =MIN(I14,MAX(0,Вводные!$B$32-H21)) | J19: =MIN(J14,MAX(0,Вводные!$B$32-I21)) | ... Y19: =MIN(Y14,MAX(0,Вводные!$B$32-X21)) | Z19: =SUM(B19:Y19)
A20: Транш кредита | B20: =B14-B19 | C20: =C14-C19 | D20: =D14-D19 | E20: =E14-E19 | F20: =F14-F19 | G20: =G14-G19 | H20: =H14-H19 | I20: =I14-I19 | ... Y20: =Y14-Y19 | Z20: =SUM(B20:Y20)
A21: Собственные средства использованы, накопительно | B21: =B19 | C21: =B21+C19 | D21: =C21+D19 | E21: =D21+E19 | F21: =E21+F19 | G21: =F21+G19 | H21: =G21+H19 | I21: =H21+I19 | J21: =I21+J19 | ... Y21: =X21+Y19
A22: Долг выбран, накопительно | B22: =B20 | C22: =B22+C20 | D22: =C22+D20 | E22: =D22+E20 | F22: =E22+F20 | G22: =F22+G20 | H22: =G22+H20 | I22: =H22+I20 | J22: =I22+J20 | ... Y22: =X22+Y20
A24: Пример из витрины. Все цифры условные.

Sheet Модель
A1: БАЗА ОТДЫХА — ФИНАНСОВАЯ МОДЕЛЬ
A2: Годовой шаг · два денежных потока: проекта и собственника · обслуживание долга
A4: СТАТЬЯ | B4: Год 0 | C4: Год 1 | D4: Год 2 | E4: Год 3 | F4: Год 4 | G4: Год 5 | H4: Год 6 | I4: Год 7 | J4: Год 8 | K4: Год 9 | L4: Год 10 | M4: ИТОГО
A6: ИНВЕСТИЦИИ
A7: Освоение инвестиций | B7: =-SUM(Инвестфаза!B14:Инвестфаза!M14) | C7: =-SUM(Инвестфаза!N14:Инвестфаза!Y14) | D7: =0 | E7: =0 | F7: =0 | G7: =0 | H7: =0 | I7: =0 | J7: =0 | K7: =0 | L7: =0 | M7: =SUM(B7:L7)
A9: ЭКСПЛУАТАЦИЯ
A10: Загрузка, % | B10: =0 | C10: =0 | D10: =MIN(Вводные!$B$17,Вводные!$B$16+(Вводные!$B$17-Вводные!$B$16)*MIN(1,0/Вводные!$B$18)) | E10: =MIN(Вводные!$B$17,Вводные!$B$16+(Вводные!$B$17-Вводные!$B$16)*MIN(1,1/Вводные!$B$18)) | F10: =MIN(Вводные!$B$17,Вводные!$B$16+(Вводные!$B$17-Вводные!$B$16)*MIN(1,2/Вводные!$B$18)) | G10: =MIN(Вводные!$B$17,Вводные!$B$16+(Вводные!$B$17-Вводные!$B$16)*MIN(1,3/Вводные!$B$18)) | H10: =MIN(Вводные!$B$17,Вводные!$B$16+(Вводные!$B$17-Вводные!$B$16)*MIN(1,4/Вводные!$B$18)) | I10: =MIN(Вводные!$B$17,Вводные!$B$16+(Вводные!$B$17-Вводные!$B$16)*MIN(1,5/Вводные!$B$18)) | J10: =MIN(Вводные!$B$17,Вводные!$B$16+(Вводные!$B$17-Вводные!$B$16)*MIN(1,6/Вводные!$B$18)) | K10: =MIN(Вводные!$B$17,Вводные!$B$16+(Вводные!$B$17-Вводные!$B$16)*MIN(1,7/Вводные!$B$18)) | L10: =MIN(Вводные!$B$17,Вводные!$B$16+(Вводные!$B$17-Вводные!$B$16)*MIN(1,8/Вводные!$B$18))
A11: Средний тариф, ₸ за ночь | B11: =0 | C11: =0 | D11: =Вводные!$B$14*(1+Вводные!$B$15)^0 | E11: =Вводные!$B$14*(1+Вводные!$B$15)^1 | F11: =Вводные!$B$14*(1+Вводные!$B$15)^2 | G11: =Вводные!$B$14*(1+Вводные!$B$15)^3 | H11: =Вводные!$B$14*(1+Вводные!$B$15)^4 | I11: =Вводные!$B$14*(1+Вводные!$B$15)^5 | J11: =Вводные!$B$14*(1+Вводные!$B$15)^6 | K11: =Вводные!$B$14*(1+Вводные!$B$15)^7 | L11: =Вводные!$B$14*(1+Вводные!$B$15)^8
A12: Проданных ночей за год | B12: =0 | C12: =0 | D12: =Вводные!$B$8*365*D10 | E12: =Вводные!$B$8*365*E10 | F12: =Вводные!$B$8*365*F10 | G12: =Вводные!$B$8*365*G10 | H12: =Вводные!$B$8*365*H10 | I12: =Вводные!$B$8*365*I10 | J12: =Вводные!$B$8*365*J10 | K12: =Вводные!$B$8*365*K10 | L12: =Вводные!$B$8*365*L10 | M12: =SUM(B12:L12)
A13: Выручка от размещения | B13: =B12*B11 | C13: =C12*C11 | D13: =D12*D11 | E13: =E12*E11 | F13: =F12*F11 | G13: =G12*G11 | H13: =H12*H11 | I13: =I12*I11 | ... L13: =L12*L11 | M13: =SUM(B13:L13)
A14: Дополнительные доходы | B14: =B13*Вводные!$B$19 | C14: =C13*Вводные!$B$19 | D14: =D13*Вводные!$B$19 | E14: =E13*Вводные!$B$19 | F14: =F13*Вводные!$B$19 | G14: =G13*Вводные!$B$19 | H14: =H13*Вводные!$B$19 | I14: =I13*Вводные!$B$19 | ... L14: =L13*Вводные!$B$19 | M14: =SUM(B14:L14)
A15: ИТОГО ВЫРУЧКА | B15: =B13+B14 | C15: =C13+C14 | D15: =D13+D14 | E15: =E13+E14 | F15: =F13+F14 | G15: =G13+G14 | H15: =H13+H14 | I15: =I13+I14 | ... L15: =L13+L14 | M15: =SUM(B15:L15)
A16: Переменные расходы | B16: =-B15*Вводные!$B$22 | C16: =-C15*Вводные!$B$22 | D16: =-D15*Вводные!$B$22 | E16: =-E15*Вводные!$B$22 | F16: =-F15*Вводные!$B$22 | G16: =-G15*Вводные!$B$22 | H16: =-H15*Вводные!$B$22 | I16: =-I15*Вводные!$B$22 | ... L16: =-L15*Вводные!$B$22 | M16: =SUM(B16:L16)
A17: Оплата труда с налогами | B17: =0 | C17: =0 | D17: =-Вводные!$B$23*(1+Вводные!$B$24)*(1+Вводные!$B$29)^0 | E17: =-Вводные!$B$23*(1+Вводные!$B$24)*(1+Вводные!$B$29)^1 | F17: =-Вводные!$B$23*(1+Вводные!$B$24)*(1+Вводные!$B$29)^2 | G17: =-Вводные!$B$23*(1+Вводные!$B$24)*(1+Вводные!$B$29)^3 | H17: =-Вводные!$B$23*(1+Вводные!$B$24)*(1+Вводные!$B$29)^4 | I17: =-Вводные!$B$23*(1+Вводные!$B$24)*(1+Вводные!$B$29)^5 | J17: =-Вводные!$B$23*(1+Вводные!$B$24)*(1+Вводные!$B$29)^6 | K17: =-Вводные!$B$23*(1+Вводные!$B$24)*(1+Вводные!$B$29)^7 | L17: =-Вводные!$B$23*(1+Вводные!$B$24)*(1+Вводные!$B$29)^8 | M17: =SUM(B17:L17)
A18: Коммунальные услуги | B18: =0 | C18: =0 | D18: =-Вводные!$B$25*(1+Вводные!$B$29)^0 | E18: =-Вводные!$B$25*(1+Вводные!$B$29)^1 | F18: =-Вводные!$B$25*(1+Вводные!$B$29)^2 | G18: =-Вводные!$B$25*(1+Вводные!$B$29)^3 | H18: =-Вводные!$B$25*(1+Вводные!$B$29)^4 | I18: =-Вводные!$B$25*(1+Вводные!$B$29)^5 | J18: =-Вводные!$B$25*(1+Вводные!$B$29)^6 | K18: =-Вводные!$B$25*(1+Вводные!$B$29)^7 | L18: =-Вводные!$B$25*(1+Вводные!$B$29)^8 | M18: =SUM(B18:L18)
A19: Текущий ремонт и содержание | B19: =0 | C19: =0 | D19: =-Вводные!$B$26*(1+Вводные!$B$29)^0 | E19: =-Вводные!$B$26*(1+Вводные!$B$29)^1 | F19: =-Вводные!$B$26*(1+Вводные!$B$29)^2 | G19: =-Вводные!$B$26*(1+Вводные!$B$29)^3 | H19: =-Вводные!$B$26*(1+Вводные!$B$29)^4 | I19: =-Вводные!$B$26*(1+Вводные!$B$29)^5 | J19: =-Вводные!$B$26*(1+Вводные!$B$29)^6 | K19: =-Вводные!$B$26*(1+Вводные!$B$29)^7 | L19: =-Вводные!$B$26*(1+Вводные!$B$29)^8 | M19: =SUM(B19:L19)
A20: Маркетинг и каналы продаж | B20: =-B15*Вводные!$B$27 | C20: =-C15*Вводные!$B$27 | D20: =-D15*Вводные!$B$27 | E20: =-E15*Вводные!$B$27 | F20: =-F15*Вводные!$B$27 | G20: =-G15*Вводные!$B$27 | H20: =-H15*Вводные!$B$27 | I20: =-I15*Вводные!$B$27 | ... L20: =-L15*Вводные!$B$27 | M20: =SUM(B20:L20)
A21: Управление и прочие | B21: =0 | C21: =0 | D21: =-Вводные!$B$28*(1+Вводные!$B$29)^0 | E21: =-Вводные!$B$28*(1+Вводные!$B$29)^1 | F21: =-Вводные!$B$28*(1+Вводные!$B$29)^2 | G21: =-Вводные!$B$28*(1+Вводные!$B$29)^3 | H21: =-Вводные!$B$28*(1+Вводные!$B$29)^4 | I21: =-Вводные!$B$28*(1+Вводные!$B$29)^5 | J21: =-Вводные!$B$28*(1+Вводные!$B$29)^6 | K21: =-Вводные!$B$28*(1+Вводные!$B$29)^7 | L21: =-Вводные!$B$28*(1+Вводные!$B$29)^8 | M21: =SUM(B21:L21)
A22: Итого операционные расходы | B22: =SUM(B16:B21) | C22: =SUM(C16:C21) | D22: =SUM(D16:D21) | E22: =SUM(E16:E21) | F22: =SUM(F16:F21) | G22: =SUM(G16:G21) | H22: =SUM(H16:H21) | I22: =SUM(I16:I21) | ... L22: =SUM(L16:L21) | M22: =SUM(B22:L22)
A23: EBITDA | B23: =B15+B22 | C23: =C15+C22 | D23: =D15+D22 | E23: =E15+E22 | F23: =F15+F22 | G23: =G15+G22 | H23: =H15+H22 | I23: =I15+I22 | ... L23: =L15+L22 | M23: =SUM(B23:L23)
A24: Рентабельность по EBITDA, % | B24: =IF(B15=0,0,B23/B15) | C24: =IF(C15=0,0,C23/C15) | D24: =IF(D15=0,0,D23/D15) | E24: =IF(E15=0,0,E23/E15) | F24: =IF(F15=0,0,F23/F15) | G24: =IF(G15=0,0,G23/G15) | H24: =IF(H15=0,0,H23/H15) | I24: =IF(I15=0,0,I23/I15) | ... L24: =IF(L15=0,0,L23/L15)
A25: Выручка на дом в год, ₸ | B25: =IF(Вводные!$B$8=0,0,B15/Вводные!$B$8) | C25: =IF(Вводные!$B$8=0,0,C15/Вводные!$B$8) | D25: =IF(Вводные!$B$8=0,0,D15/Вводные!$B$8) | E25: =IF(Вводные!$B$8=0,0,E15/Вводные!$B$8) | F25: =IF(Вводные!$B$8=0,0,F15/Вводные!$B$8) | G25: =IF(Вводные!$B$8=0,0,G15/Вводные!$B$8) | H25: =IF(Вводные!$B$8=0,0,H15/Вводные!$B$8) | I25: =IF(Вводные!$B$8=0,0,I15/Вводные!$B$8) | ... L25: =IF(Вводные!$B$8=0,0,L15/Вводные!$B$8)
A27: ДОЛГ И ПРИБЫЛЬ
A28: Получение кредита | B28: =SUM(Инвестфаза!B20:M20) | C28: =SUM(Инвестфаза!N20:Y20) | D28: =0 | E28: =0 | F28: =0 | G28: =0 | H28: =0 | I28: =0 | J28: =0 | K28: =0 | L28: =0 | M28: =SUM(B28:L28)
A29: Проценты по кредиту | B29: =0 | C29: =-B31*Вводные!$B$34 | D29: =-C31*Вводные!$B$34 | E29: =-D31*Вводные!$B$34 | F29: =-E31*Вводные!$B$34 | G29: =-F31*Вводные!$B$34 | H29: =-G31*Вводные!$B$34 | I29: =-H31*Вводные!$B$34 | J29: =-I31*Вводные!$B$34 | ... L29: =-K31*Вводные!$B$34 | M29: =SUM(B29:L29)
A30: Погашение тела | B30: =0 | C30: =0 | D30: =-IF(2<Вводные!$B$36,0,MIN(M28/(Вводные!$B$35-Вводные!$B$36),MAX(0,C31))) | E30: =-IF(3<Вводные!$B$36,0,MIN(M28/(Вводные!$B$35-Вводные!$B$36),MAX(0,D31))) | F30: =-IF(4<Вводные!$B$36,0,MIN(M28/(Вводные!$B$35-Вводные!$B$36),MAX(0,E31))) | G30: =-IF(5<Вводные!$B$36,0,MIN(M28/(Вводные!$B$35-Вводные!$B$36),MAX(0,F31))) | H30: =-IF(6<Вводные!$B$36,0,MIN(M28/(Вводные!$B$35-Вводные!$B$36),MAX(0,G31))) | I30: =-IF(7<Вводные!$B$36,0,MIN(M28/(Вводные!$B$35-Вводные!$B$36),MAX(0,H31))) | J30: =-IF(8<Вводные!$B$36,0,MIN(M28/(Вводные!$B$35-Вводные!$B$36),MAX(0,I31))) | K30: =-IF(9<Вводные!$B$36,0,MIN(M28/(Вводные!$B$35-Вводные!$B$36),MAX(0,J31))) | L30: =-IF(10<Вводные!$B$36,0,MIN(M28/(Вводные!$B$35-Вводные!$B$36),MAX(0,K31))) | M30: =SUM(B30:L30)
A31: Остаток долга на конец года | B31: =B28+B30 | C31: =B31+C28+C30 | D31: =C31+D28+D30 | E31: =D31+E28+E30 | F31: =E31+F28+F30 | G31: =F31+G28+G30 | H31: =G31+H28+H30 | I31: =H31+I28+I30 | J31: =I31+J28+J30 | ... L31: =K31+L28+L30
A32: Амортизация | B32: =0 | C32: =0 | D32: =-(Вводные!$B$11-Вводные!$B$5)/Вводные!$B$38 | E32: =-(Вводные!$B$11-Вводные!$B$5)/Вводные!$B$38 | F32: =-(Вводные!$B$11-Вводные!$B$5)/Вводные!$B$38 | G32: =-(Вводные!$B$11-Вводные!$B$5)/Вводные!$B$38 | H32: =-(Вводные!$B$11-Вводные!$B$5)/Вводные!$B$38 | I32: =-(Вводные!$B$11-Вводные!$B$5)/Вводные!$B$38 | J32: =-(Вводные!$B$11-Вводные!$B$5)/Вводные!$B$38 | K32: =-(Вводные!$B$11-Вводные!$B$5)/Вводные!$B$38 | L32: =-(Вводные!$B$11-Вводные!$B$5)/Вводные!$B$38 | M32: =SUM(B32:L32)
A33: Прибыль до налога | B33: =B23+B32+B29 | C33: =C23+C32+C29 | D33: =D23+D32+D29 | E33: =E23+E32+E29 | F33: =F23+F32+F29 | G33: =G23+G32+G29 | H33: =H23+H32+H29 | I33: =I23+I32+I29 | ... L33: =L23+L32+L29 | M33: =SUM(B33:L33)
A34: Корпоративный подоходный налог | B34: =-MAX(0,B33)*Вводные!$B$39 | C34: =-MAX(0,C33)*Вводные!$B$39 | D34: =-MAX(0,D33)*Вводные!$B$39 | E34: =-MAX(0,E33)*Вводные!$B$39 | F34: =-MAX(0,F33)*Вводные!$B$39 | G34: =-MAX(0,G33)*Вводные!$B$39 | H34: =-MAX(0,H33)*Вводные!$B$39 | I34: =-MAX(0,I33)*Вводные!$B$39 | ... L34: =-MAX(0,L33)*Вводные!$B$39 | M34: =SUM(B34:L34)
A35: ЧИСТАЯ ПРИБЫЛЬ | B35: =B33+B34 | C35: =C33+C34 | D35: =D33+D34 | E35: =E33+E34 | F35: =F33+F34 | G35: =G33+G34 | H35: =H33+H34 | I35: =I33+I34 | ... L35: =L33+L34 | M35: =SUM(B35:L35)
A36: Коэффициент обслуживания долга (DSCR) | B36: ="—" | C36: ="—" | D36: =IF(-(D29+D30)<=1000,"—",(D23+D34)/-(D29+D30)) | E36: =IF(-(E29+E30)<=1000,"—",(E23+E34)/-(E29+E30)) | F36: =IF(-(F29+F30)<=1000,"—",(F23+F34)/-(F29+F30)) | G36: =IF(-(G29+G30)<=1000,"—",(G23+G34)/-(G29+G30)) | H36: =IF(-(H29+H30)<=1000,"—",(H23+H34)/-(H29+H30)) | I36: =IF(-(I29+I30)<=1000,"—",(I23+I34)/-(I29+I30)) | J36: =IF(-(J29+J30)<=1000,"—",(J23+J34)/-(J29+J30)) | K36: =IF(-(K29+K30)<=1000,"—",(K23+K34)/-(K29+K30)) | L36: =IF(-(L29+L30)<=1000,"—",(L23+L34)/-(L29+L30))
A38: ДЕНЕЖНЫЕ ПОТОКИ
A39: Стоимость объекта при выходе | B39: =0 | C39: =0 | D39: =0 | E39: =0 | F39: =0 | G39: =0 | H39: =0 | I39: =0 | ... K39: =0 | L39: =L23*Вводные!$B$40 | M39: =SUM(B39:L39)
A40: Денежный поток проекта | B40: =B23+B34+B7+B39 | C40: =C23+C34+C7+C39 | D40: =D23+D34+D7+D39 | E40: =E23+E34+E7+E39 | F40: =F23+F34+F7+F39 | G40: =G23+G34+G7+G39 | H40: =H23+H34+H7+H39 | I40: =I23+I34+I7+I39 | ... L40: =L23+L34+L7+L39 | M40: =SUM(B40:L40)
A41: Денежный поток собственника | B41: =B40+B28+B29+B30-IF(0=10,B31,0) | C41: =C40+C28+C29+C30-IF(1=10,C31,0) | D41: =D40+D28+D29+D30-IF(2=10,D31,0) | E41: =E40+E28+E29+E30-IF(3=10,E31,0) | F41: =F40+F28+F29+F30-IF(4=10,F31,0) | G41: =G40+G28+G29+G30-IF(5=10,G31,0) | H41: =H40+H28+H29+H30-IF(6=10,H31,0) | I41: =I40+I28+I29+I30-IF(7=10,I31,0) | J41: =J40+J28+J29+J30-IF(8=10,J31,0) | K41: =K40+K28+K29+K30-IF(9=10,K31,0) | L41: =L40+L28+L29+L30-IF(10=10,L31,0) | M41: =SUM(B41:L41)
A42: Коэффициент дисконтирования | B42: =1/(1+Вводные!$B$43)^0 | C42: =1/(1+Вводные!$B$43)^1 | D42: =1/(1+Вводные!$B$43)^2 | E42: =1/(1+Вводные!$B$43)^3 | F42: =1/(1+Вводные!$B$43)^4 | G42: =1/(1+Вводные!$B$43)^5 | H42: =1/(1+Вводные!$B$43)^6 | I42: =1/(1+Вводные!$B$43)^7 | J42: =1/(1+Вводные!$B$43)^8 | K42: =1/(1+Вводные!$B$43)^9 | L42: =1/(1+Вводные!$B$43)^10
A43: Дисконтированный поток проекта | B43: =B40*B42 | C43: =C40*C42 | D43: =D40*D42 | E43: =E40*E42 | F43: =F40*F42 | G43: =G40*G42 | H43: =H40*H42 | I43: =I40*I42 | ... L43: =L40*L42 | M43: =SUM(B43:L43)
A44: Накопленный дисконтированный поток | B44: =B43 | C44: =B44+C43 | D44: =C44+D43 | E44: =D44+E43 | F44: =E44+F43 | G44: =F44+G43 | H44: =G44+H43 | I44: =H44+I43 | J44: =I44+J43 | ... L44: =K44+L43
A46: Пример из витрины. Все цифры условные и не относятся к какому-либо действующему проекту.

Sheet Чувствительность
A1: ЧУВСТВИТЕЛЬНОСТЬ И СЦЕНАРИИ
A2: NPV проекта при разных сочетаниях загрузки и тарифа · 25 расчётов
M4: NPV | N4: IRR
A5: Пересчёт денежного потока проекта для каждой комбинации
A6: Загрузка -10% · тариф -10% | B6: =Модель!B7 | C6: =Модель!C7 | D6: =((Вводные!$B$8*365*MIN((Вводные!$B$17+-0.1),Вводные!$B$16+((Вводные!$B$17+-0.1)-Вводные!$B$16)*MIN(1,0/Вводные!$B$18))*(Вводные!$B$14*(1+-0.1))*(1+Вводные!$B$15)^0*(1+Вводные!$B$19))*(1-Вводные!$B$22-Вводные!$B$27)+(Модель!D17+Модель!D18+Модель!D19+Модель!D21))-MAX(0,((Вводные!$B$8*365*MIN((Вводные!$B$17+-0.1),Вводные!$B$16+((Вводные!$B$17+-0.1)-Вводные!$B$16)*MIN(1,0/Вводные!$B$18))*(Вводные!$B$14*(1+-0.1))*(1+Вводные!$B$15)^0*(1+Вводные!$B$19))*(1-Вводные!$B$22-Вводные!$B$27)+(Модель!D17+Модель!D18+Модель!D19+Модель!D21))+Модель!D32+Модель!D29)*Вводные!$B$39 | E6: =((Вводные!$B$8*365*MIN((Вводные!$B$17+-0.1),Вводные!$B$16+((Вводные!$B$17+-0.1)-Вводные!$B$16)*MIN(1,1/Вводные!$B$18))*(Вводные!$B$14*(1+-0.1))*(1+Вводные!$B$15)^1*(1+Вводные!$B$19))*(1-Вводные!$B$22-Вводные!$B$27)+(Модель!E17+Модель!E18+Модель!E19+Модель!E21))-MAX(0,((Вводные!$B$8*365*MIN((Вводные!$B$17+-0.1),Вводные!$B$16+((Вводные!$B$17+-0.1)-Вводные!$B$16)*MIN(1,1/Вводные!$B$18))*(Вводные!$B$14*(1+-0.1))*(1+Вводные!$B$15)^1*(1+Вводные!$B$19))*(1-Вводные!$B$22-Вводные!$B$27)+(Модель!E17+Модель!E18+Модель!E19+Модель!E21))+Модель!E32+Модель!E29)*Вводные!$B$39 | F6: =((Вводные!$B$8*365*MIN((Вводные!$B$17+-0.1),Вводные!$B$16+((Вводные!$B$17+-0.1)-Вводные!$B$16)*MIN(1,2/Вводные!$B$18))*(Вводные!$B$14*(1+-0.1))*(1+Вводные!$B$15)^2*(1+Вводные!$B$19))*(1-Вводные!$B$22-Вводные!$B$27)+(Модель!F17+Модель!F18+Модель!F19+Модель!F21))-MAX(0,((Вводные!$B$8*365*MIN((Вводные!$B$17+-0.1),Вводные!$B$16+((Вводные!$B$17+-0.1)-Вводные!$B$16)*MIN(1,2/Вводные!$B$18))*(Вводные!$B$14*(1+-0.1))*(1+Вводные!$B$15)^2*(1+Вводные!$B$19))*(1-Вводные!$B$22-Вводные!$B$27)+(Модель!F17+Модель!F18+Модель!F19+Модель!F21))+Модель!F32+Модель!F29)*Вводные!$B$39 | G6: =((Вводные!$B$8*365*MIN((Вводные!$B$17+-0.1),Вводные!$B$16+((Вводные!$B$17+-0.1)-Вводные!$B$16)*MIN(1,3/Вводные!$B$18))*(Вводные!$B$14*(1+-0.1))*(1+Вводные!$B$15)^3*(1+Вводные!$B$19))*(1-Вводные!$B$22-Вводные!$B$27)+(Модель!G17+Модель!G18+Модель!G19+Модель!G21))-MAX(0,((Вводные!$B$8*365*MIN((Вводные!$B$17+-0.1),Вводные!$B$16+((Вводные!$B$17+-0.1)-Вводные!$B$16)*MIN(1,3/Вводные!$B$18))*(Вводные!$B$14*(1+-0.1))*(1+Вводные!$B$15)^3*(1+Вводные!$B$19))*(1-Вводные!$B$22-Вводные!$B$27)+(Модель!G17+Модель!G18+Модель!G19+Модель!G21))+Модель!G32+Модель!G29)*Вводные!$B$39 | H6: =((Вводные!$B$8*365*MIN((Вводные!$B$17+-0.1),Вводные!$B$16+((Вводные!$B$17+-0.1)-Вводные!$B$16)*MIN(1,4/Вводные!$B$18))*(Вводные!$B$14*(1+-0.1))*(1+Вводные!$B$15)^4*(1+Вводные!$B$19))*(1-Вводные!$B$22-Вводные!$B$27)+(Модель!H17+Модель!H18+Модель!H19+Модель!H21))-MAX(0,((Вводные!$B$8*365*MIN((Вводные!$B$17+-0.1),Вводные!$B$16+((Вводные!$B$17+-0.1)-Вводные!$B$16)*MIN(1,4/Вводные!$B$18))*(Вводные!$B$14*(1+-0.1))*(1+Вводные!$B$15)^4*(1+Вводные!$B$19))*(1-Вводные!$B$22-Вводные!$B$27)+(Модель!H17+Модель!H18+Модель!H19+Модель!H21))+Модель!H32+Модель!H29)*Вводные!$B$39 | I6: =((Вводные!$B$8*365*MIN((Вводные!$B$17+-0.1),Вводные!$B$16+((Вводные!$B$17+-0.1)-Вводные!$B$16)*MIN(1,5/Вводные!$B$18))*(Вводные!$B$14*(1+-0.1))*(1+Вводные!$B$15)^5*(1+Вводные!$B$19))*(1-Вводные!$B$22-Вводные!$B$27)+(Модель!I17+Модель!I18+Модель!I19+Модель!I21))-MAX(0,((Вводные!$B$8*365*MIN((Вводные!$B$17+-0.1),Вводные!$B$16+((Вводные!$B$17+-0.1)-Вводные!$B$16)*MIN(1,5/Вводные!$B$18))*(Вводные!$B$14*(1+-0.1))*(1+Вводные!$B$15)^5*(1+Вводные!$B$19))*(1-Вводные!$B$22-Вводные!$B$27)+(Модель!I17+Модель!I18+Модель!I19+Модель!I21))+Модель!I32+Модель!I29)*Вводные!$B$39 | J6: =((Вводные!$B$8*365*MIN((Вводные!$B$17+-0.1),Вводные!$B$16+((Вводные!$B$17+-0.1)-Вводные!$B$16)*MIN(1,6/Вводные!$B$18))*(Вводные!$B$14*(1+-0.1))*(1+Вводные!$B$15)^6*(1+Вводные!$B$19))*(1-Вводные!$B$22-Вводные!$B$27)+(Модель!J17+Модель!J18+Модель!J19+Модель!J21))-MAX(0,((Вводные!$B$8*365*MIN((Вводные!$B$17+-0.1),Вводные!$B$16+((Вводные!$B$17+-0.1)-Вводные!$B$16)*MIN(1,6/Вводные!$B$18))*(Вводные!$B$14*(1+-0.1))*(1+Вводные!$B$15)^6*(1+Вводные!$B$19))*(1-Вводные!$B$22-Вводные!$B$27)+(Модель!J17+Модель!J18+Модель!J19+Модель!J21))+Модель!J32+Модель!J29)*Вводные!$B$39 | K6: =((Вводные!$B$8*365*MIN((Вводные!$B$17+-0.1),Вводные!$B$16+((Вводные!$B$17+-0.1)-Вводные!$B$16)*MIN(1,7/Вводные!$B$18))*(Вводные!$B$14*(1+-0.1))*(1+Вводные!$B$15)^7*(1+Вводные!$B$19))*(1-Вводные!$B$22-Вводные!$B$27)+(Модель!K17+Модель!K18+Модель!K19+Модель!K21))-MAX(0,((Вводные!$B$8*365*MIN((Вводные!$B$17+-0.1),Вводные!$B$16+((Вводные!$B$17+-0.1)-Вводные!$B$16)*MIN(1,7/Вводные!$B$18))*(Вводные!$B$14*(1+-0.1))*(1+Вводные!$B$15)^7*(1+Вводные!$B$19))*(1-Вводные!$B$22-Вводные!$B$27)+(Модель!K17+Модель!K18+Модель!K19+Модель!K21))+Модель!K32+Модель!K29)*Вводные!$B$39 | L6: =((Вводные!$B$8*365*MIN((Вводные!$B$17+-0.1),Вводные!$B$16+((Вводные!$B$17+-0.1)-Вводные!$B$16)*MIN(1,8/Вводные!$B$18))*(Вводные!$B$14*(1+-0.1))*(1+Вводные!$B$15)^8*(1+Вводные!$B$19))*(1-Вводные!$B$22-Вводные!$B$27)+(Модель!L17+Модель!L18+Модель!L19+Модель!L21))-MAX(0,((Вводные!$B$8*365*MIN((Вводные!$B$17+-0.1),Вводные!$B$16+((Вводные!$B$17+-0.1)-Вводные!$B$16)*MIN(1,8/Вводные!$B$18))*(Вводные!$B$14*(1+-0.1))*(1+Вводные!$B$15)^8*(1+Вводные!$B$19))*(1-Вводные!$B$22-Вводные!$B$27)+(Модель!L17+Модель!L18+Модель!L19+Модель!L21))+Модель!L32+Модель!L29)*Вводные!$B$39+((Вводные!$B$8*365*MIN((Вводные!$B$17+-0.1),Вводные!$B$16+((Вводные!$B$17+-0.1)-Вводные!$B$16)*MIN(1,8/Вводные!$B$18))*(Вводные!$B$14*(1+-0.1))*(1+Вводные!$B$15)^8*(1+Вводные!$B$19))*(1-Вводные!$B$22-Вводные!$B$27)+(Модель!L17+Модель!L18+Модель!L19+Модель!L21))*Вводные!$B$40 | M6: =SUMPRODUCT(B6:L6,Модель!$B$42:$L$42) | N6: =IFERROR(IRR(B6:L6),"—")
A7: Загрузка -10% · тариф -5% | B7: =Модель!B7 | C7: =Модель!C7 | D7: =((Вводные!$B$8*365*MIN((Вводные!$B$17+-0.1),Вводные!$B$16+((Вводные!$B$17+-0.1)-Вводные!$B$16)*MIN(1,0/Вводные!$B$18))*(Вводные!$B$14*(1+-0.05))*(1+Вводные!$B$15)^0*(1+Вводные!$B$19))*(1-Вводные!$B$22-Вводные!$B$27)+(Модель!D17+Модель!D18+Модель!D19+Модель!D21))-MAX(0,((Вводные!$B$8*365*MIN((Вводные!$B$17+-0.1),Вводные!$B$16+((Вводные!$B$17+-0.1)-Вводные!$B$16)*MIN(1,0/Вводные!$B$18))*(Вводные!$B$14*(1+-0.05))*(1+Вводные!$B$15)^0*(1+Вводные!$B$19))*(1-Вводные!$B$22-Вводные!$B$27)+(Модель!D17+Модель!D18+Модель!D19+Модель!D21))+Модель!D32+Модель!D29)*Вводные!$B$39 | E7: =((Вводные!$B$8*365*MIN((Вводные!$B$17+-0.1),Вводные!$B$16+((Вводные!$B$17+-0.1)-Вводные!$B$16)*MIN(1,1/Вводные!$B$18))*(Вводные!$B$14*(1+-0.05))*(1+Вводные!$B$15)^1*(1+Вводные!$B$19))*(1-Вводные!$B$22-Вводные!$B$27)+(Модель!E17+Модель!E18+Модель!E19+Модель!E21))-MAX(0,((Вводные!$B$8*365*MIN((Вводные!$B$17+-0.1),Вводные!$B$16+((Вводные!$B$17+-0.1)-Вводные!$B$16)*MIN(1,1/Вводные!$B$18))*(Вводные!$B$14*(1+-0.05))*(1+Вводные!$B$15)^1*(1+Вводные!$B$19))*(1-Вводные!$B$22-Вводные!$B$27)+(Модель!E17+Модель!E18+Модель!E19+Модель!E21))+Модель!E32+Модель!E29)*Вводные!$B$39 | F7: =((Вводные!$B$8*365*MIN((Вводные!$B$17+-0.1),Вводные!$B$16+((Вводные!$B$17+-0.1)-Вводные!$B$16)*MIN(1,2/Вводные!$B$18))*(Вводные!$B$14*(1+-0.05))*(1+Вводные!$B$15)^2*(1+Вводные!$B$19))*(1-Вводные!$B$22-Вводные!$B$27)+(Модель!F17+Модель!F18+Модель!F19+Модель!F21))-MAX(0,((Вводные!$B$8*365*MIN((Вводные!$B$17+-0.1),Вводные!$B$16+((Вводные!$B$17+-0.1)-Вводные!$B$16)*MIN(1,2/Вводные!$B$18))*(Вводные!$B$14*(1+-0.05))*(1+Вводные!$B$15)^2*(1+Вводные!$B$19))*(1-Вводные!$B$22-Вводные!$B$27)+(Модель!F17+Модель!F18+Модель!F19+Модель!F21))+Модель!F32+Модель!F29)*Вводные!$B$39 | G7: =((Вводные!$B$8*365*MIN((Вводные!$B$17+-0.1),Вводные!$B$16+((Вводные!$B$17+-0.1)-Вводные!$B$16)*MIN(1,3/Вводные!$B$18))*(Вводные!$B$14*(1+-0.05))*(1+Вводные!$B$15)^3*(1+Вводные!$B$19))*(1-Вводные!$B$22-Вводные!$B$27)+(Модель!G17+Модель!G18+Модель!G19+Модель!G21))-MAX(0,((Вводные!$B$8*365*MIN((Вводные!$B$17+-0.1),Вводные!$B$16+((Вводные!$B$17+-0.1)-Вводные!$B$16)*MIN(1,3/Вводные!$B$18))*(Вводные!$B$14*(1+-0.05))*(1+Вводные!$B$15)^3*(1+Вводные!$B$19))*(1-Вводные!$B$22-Вводные!$B$27)+(Модель!G17+Модель!G18+Модель!G19+Модель!G21))+Модель!G32+Модель!G29)*Вводные!$B$39 | H7: =((Вводные!$B$8*365*MIN((Вводные!$B$17+-0.1),Вводные!$B$16+((Вводные!$B$17+-0.1)-Вводные!$B$16)*MIN(1,4/Вводные!$B$18))*(Вводные!$B$14*(1+-0.05))*(1+Вводные!$B$15)^4*(1+Вводные!$B$19))*(1-Вводные!$B$22-Вводные!$B$27)+(Модель!H17+Модель!H18+Модель!H19+Модель!H21))-MAX(0,((Вводные!$B$8*365*MIN((Вводные!$B$17+-0.1),Вводные!$B$16+((Вводные!$B$17+-0.1)-Вводные!$B$16)*MIN(1,4/Вводные!$B$18))*(Вводные!$B$14*(1+-0.05))*(1+Вводные!$B$15)^4*(1+Вводные!$B$19))*(1-Вводные!$B$22-Вводные!$B$27)+(Модель!H17+Модель!H18+Модель!H19+Модель!H21))+Модель!H32+Модель!H29)*Вводные!$B$39 | I7: =((Вводные!$B$8*365*MIN((Вводные!$B$17+-0.1),Вводные!$B$16+((Вводные!$B$17+-0.1)-Вводные!$B$16)*MIN(1,5/Вводные!$B$18))*(Вводные!$B$14*(1+-0.05))*(1+Вводные!$B$15)^5*(1+Вводные!$B$19))*(1-Вводные!$B$22-Вводные!$B$27)+(Модель!I17+Модель!I18+Модель!I19+Модель!I21))-MAX(0,((Вводные!$B$8*365*MIN((Вводные!$B$17+-0.1),Вводные!$B$16+((Вводные!$B$17+-0.1)-Вводные!$B$16)*MIN(1,5/Вводные!$B$18))*(Вводные!$B$14*(1+-0.05))*(1+Вводные!$B$15)^5*(1+Вводные!$B$19))*(1-Вводные!$B$22-Вводные!$B$27)+(Модель!I17+Модель!I18+Модель!I19+Модель!I21))+Модель!I32+Модель!I29)*Вводные!$B$39 | J7: =((Вводные!$B$8*365*MIN((Вводные!$B$17+-0.1),Вводные!$B$16+((Вводные!$B$17+-0.1)-Вводные!$B$16)*MIN(1,6/Вводные!$B$18))*(Вводные!$B$14*(1+-0.05))*(1+Вводные!$B$15)^6*(1+Вводные!$B$19))*(1-Вводные!$B$22-Вводные!$B$27)+(Модель!J17+Модель!J18+Модель!J19+Модель!J21))-MAX(0,((Вводные!$B$8*365*MIN((Вводные!$B$17+-0.1),Вводные!$B$16+((Вводные!$B$17+-0.1)-Вводные!$B$16)*MIN(1,6/Вводные!$B$18))*(Вводные!$B$14*(1+-0.05))*(1+Вводные!$B$15)^6*(1+Вводные!$B$19))*(1-Вводные!$B$22-Вводные!$B$27)+(Модель!J17+Модель!J18+Модель!J19+Модель!J21))+Модель!J32+Модель!J29)*Вводные!$B$39 | K7: =((Вводные!$B$8*365*MIN((Вводные!$B$17+-0.1),Вводные!$B$16+((Вводные!$B$17+-0.1)-Вводные!$B$16)*MIN(1,7/Вводные!$B$18))*(Вводные!$B$14*(1+-0.05))*(1+Вводные!$B$15)^7*(1+Вводные!$B$19))*(1-Вводные!$B$22-Вводные!$B$27)+(Модель!K17+Модель!K18+Модель!K19+Модель!K21))-MAX(0,((Вводные!$B$8*365*MIN((Вводные!$B$17+-0.1),Вводные!$B$16+((Вводные!$B$17+-0.1)-Вводные!$B$16)*MIN(1,7/Вводные!$B$18))*(Вводные!$B$14*(1+-0.05))*(1+Вводные!$B$15)^7*(1+Вводные!$B$19))*(1-Вводные!$B$22-Вводные!$B$27)+(Модель!K17+Модель!K18+Модель!K19+Модель!K21))+Модель!K32+Модель!K29)*Вводные!$B$39 | L7: =((Вводные!$B$8*365*MIN((Вводные!$B$17+-0.1),Вводные!$B$16+((Вводные!$B$17+-0.1)-Вводные!$B$16)*MIN(1,8/Вводные!$B$18))*(Вводные!$B$14*(1+-0.05))*(1+Вводные!$B$15)^8*(1+Вводные!$B$19))*(1-Вводные!$B$22-Вводные!$B$27)+(Модель!L17+Модель!L18+Модель!L19+Модель!L21))-MAX(0,((Вводные!$B$8*365*MIN((Вводные!$B$17+-0.1),Вводные!$B$16+((Вводные!$B$17+-0.1)-Вводные!$B$16)*MIN(1,8/Вводные!$B$18))*(Вводные!$B$14*(1+-0.05))*(1+Вводные!$B$15)^8*(1+Вводные!$B$19))*(1-Вводные!$B$22-Вводные!$B$27)+(Модель!L17+Модель!L18+Модель!L19+Модель!L21))+Модель!L32+Модель!L29)*Вводные!$B$39+((Вводные!$B$8*365*MIN((Вводные!$B$17+-0.1),Вводные!$B$16+((Вводные!$B$17+-0.1)-Вводные!$B$16)*MIN(1,8/Вводные!$B$18))*(Вводные!$B$14*(1+-0.05))*(1+Вводные!$B$15)^8*(1+Вводные!$B$19))*(1-Вводные!$B$22-Вводные!$B$27)+(Модель!L17+Модель!L18+Модель!L19+Модель!L21))*Вводные!$B$40 | M7: =SUMPRODUCT(B7:L7,Модель!$B$42:$L$42) | N7: =IFERROR(IRR(B7:L7),"—")
A8: Загрузка -10% · тариф +0% | B8: =Модель!B7 | C8: =Модель!C7 | D8: =((Вводные!$B$8*365*MIN((Вводные!$B$17+-0.1),Вводные!$B$16+((Вводные!$B$17+-0.1)-Вводные!$B$16)*MIN(1,0/Вводные!$B$18))*(Вводные!$B$14*(1+0.0))*(1+Вводные!$B$15)^0*(1+Вводные!$B$19))*(1-Вводные!$B$22-Вводные!$B$27)+(Модель!D17+Модель!D18+Модель!D19+Модель!D21))-MAX(0,((Вводные!$B$8*365*MIN((Вводные!$B$17+-0.1),Вводные!$B$16+((Вводные!$B$17+-0.1)-Вводные!$B$16)*MIN(1,0/Вводные!$B$18))*(Вводные!$B$14*(1+0.0))*(1+Вводные!$B$15)^0*(1+Вводные!$B$19))*(1-Вводные!$B$22-Вводные!$B$27)+(Модель!D17+Модель!D18+Модель!D19+Модель!D21))+Модель!D32+Модель!D29)*Вводные!$B$39 | E8: =((Вводные!$B$8*365*MIN((Вводные!$B$17+-0.1),Вводные!$B$16+((Вводные!$B$17+-0.1)-Вводные!$B$16)*MIN(1,1/Вводные!$B$18))*(Вводные!$B$14*(1+0.0))*(1+Вводные!$B$15)^1*(1+Вводные!$B$19))*(1-Вводные!$B$22-Вводные!$B$27)+(Модель!E17+Модель!E18+Модель!E19+Модель!E21))-MAX(0,((Вводные!$B$8*365*MIN((Вводные!$B$17+-0.1),Вводные!$B$16+((Вводные!$B$17+-0.1)-Вводные!$B$16)*MIN(1,1/Вводные!$B$18))*(Вводные!$B$14*(1+0.0))*(1+Вводные!$B$15)^1*(1+Вводные!$B$19))*(1-Вводные!$B$22-Вводные!$B$27)+(Модель!E17+Модель!E18+Модель!E19+Модель!E21))+Модель!E32+Модель!E29)*Вводные!$B$39 | F8: =((Вводные!$B$8*365*MIN((Вводные!$B$17+-0.1),Вводные!$B$16+((Вводные!$B$17+-0.1)-Вводные!$B$16)*MIN(1,2/Вводные!$B$18))*(Вводные!$B$14*(1+0.0))*(1+Вводные!$B$15)^2*(1+Вводные!$B$19))*(1-Вводные!$B$22-Вводные!$B$27)+(Модель!F17+Модель!F18+Модель!F19+Модель!F21))-MAX(0,((Вводные!$B$8*365*MIN((Вводные!$B$17+-0.1),Вводные!$B$16+((Вводные!$B$17+-0.1)-Вводные!$B$16)*MIN(1,2/Вводные!$B$18))*(Вводные!$B$14*(1+0.0))*(1+Вводные!$B$15)^2*(1+Вводные!$B$19))*(1-Вводные!$B$22-Вводные!$B$27)+(Модель!F17+Модель!F18+Модель!F19+Модель!F21))+Модель!F32+Модель!F29)*Вводные!$B$39 | G8: =((Вводные!$B$8*365*MIN((Вводные!$B$17+-0.1),Вводные!$B$16+((Вводные!$B$17+-0.1)-Вводные!$B$16)*MIN(1,3/Вводные!$B$18))*(Вводные!$B$14*(1+0.0))*(1+Вводные!$B$15)^3*(1+Вводные!$B$19))*(1-Вводные!$B$22-Вводные!$B$27)+(Модель!G17+Модель!G18+Модель!G19+Модель!G21))-MAX(0,((Вводные!$B$8*365*MIN((Вводные!$B$17+-0.1),Вводные!$B$16+((Вводные!$B$17+-0.1)-Вводные!$B$16)*MIN(1,3/Вводные!$B$18))*(Вводные!$B$14*(1+0.0))*(1+Вводные!$B$15)^3*(1+Вводные!$B$19))*(1-Вводные!$B$22-Вводные!$B$27)+(Модель!G17+Модель!G18+Модель!G19+Модель!G21))+Модель!G32+Модель!G29)*Вводные!$B$39 | H8: =((Вводные!$B$8*365*MIN((Вводные!$B$17+-0.1),Вводные!$B$16+((Вводные!$B$17+-0.1)-Вводные!$B$16)*MIN(1,4/Вводные!$B$18))*(Вводные!$B$14*(1+0.0))*(1+Вводные!$B$15)^4*(1+Вводные!$B$19))*(1-Вводные!$B$22-Вводные!$B$27)+(Модель!H17+Модель!H18+Модель!H19+Модель!H21))-MAX(0,((Вводные!$B$8*365*MIN((Вводные!$B$17+-0.1),Вводные!$B$16+((Вводные!$B$17+-0.1)-Вводные!$B$16)*MIN(1,4/Вводные!$B$18))*(Вводные!$B$14*(1+0.0))*(1+Вводные!$B$15)^4*(1+Вводные!$B$19))*(1-Вводные!$B$22-Вводные!$B$27)+(Модель!H17+Модель!H18+Модель!H19+Модель!H21))+Модель!H32+Модель!H29)*Вводные!$B$39 | I8: =((Вводные!$B$8*365*MIN((Вводные!$B$17+-0.1),Вводные!$B$16+((Вводные!$B$17+-0.1)-Вводные!$B$16)*MIN(1,5/Вводные!$B$18))*(Вводные!$B$14*(1+0.0))*(1+Вводные!$B$15)^5*(1+Вводные!$B$19))*(1-Вводные!$B$22-Вводные!$B$27)+(Модель!I17+Модель!I18+Модель!I19+Модель!I21))-MAX(0,((Вводные!$B$8*365*MIN((Вводные!$B$17+-0.1),Вводные!$B$16+((Вводные!$B$17+-0.1)-Вводные!$B$16)*MIN(1,5/Вводные!$B$18))*(Вводные!$B$14*(1+0.0))*(1+Вводные!$B$15)^5*(1+Вводные!$B$19))*(1-Вводные!$B$22-Вводные!$B$27)+(Модель!I17+Модель!I18+Модель!I19+Модель!I21))+Модель!I32+Модель!I29)*Вводные!$B$39 | J8: =((Вводные!$B$8*365*MIN((Вводные!$B$17+-0.1),Вводные!$B$16+((Вводные!$B$17+-0.1)-Вводные!$B$16)*MIN(1,6/Вводные!$B$18))*(Вводные!$B$14*(1+0.0))*(1+Вводные!$B$15)^6*(1+Вводные!$B$19))*(1-Вводные!$B$22-Вводные!$B$27)+(Модель!J17+Модель!J18+Модель!J19+Модель!J21))-MAX(0,((Вводные!$B$8*365*MIN((Вводные!$B$17+-0.1),Вводные!$B$16+((Вводные!$B$17+-0.1)-Вводные!$B$16)*MIN(1,6/Вводные!$B$18))*(Вводные!$B$14*(1+0.0))*(1+Вводные!$B$15)^6*(1+Вводные!$B$19))*(1-Вводные!$B$22-Вводные!$B$27)+(Модель!J17+Модель!J18+Модель!J19+Модель!J21))+Модель!J32+Модель!J29)*Вводные!$B$39 | K8: =((Вводные!$B$8*365*MIN((Вводные!$B$17+-0.1),Вводные!$B$16+((Вводные!$B$17+-0.1)-Вводные!$B$16)*MIN(1,7/Вводные!$B$18))*(Вводные!$B$14*(1+0.0))*(1+Вводные!$B$15)^7*(1+Вводные!$B$19))*(1-Вводные!$B$22-Вводные!$B$27)+(Модель!K17+Модель!K18+Модель!K19+Модель!K21))-MAX(0,((Вводные!$B$8*365*MIN((Вводные!$B$17+-0.1),Вводные!$B$16+((Вводные!$B$17+-0.1)-Вводные!$B$16)*MIN(1,7/Вводные!$B$18))*(Вводные!$B$14*(1+0.0))*(1+Вводные!$B$15)^7*(1+Вводные!$B$19))*(1-Вводные!$B$22-Вводные!$B$27)+(Модель!K17+Модель!K18+Модель!K19+Модель!K21))+Модель!K32+Модель!K29)*Вводные!$B$39 | L8: =((Вводные!$B$8*365*MIN((Вводные!$B$17+-0.1),Вводные!$B$16+((Вводные!$B$17+-0.1)-Вводные!$B$16)*MIN(1,8/Вводные!$B$18))*(Вводные!$B$14*(1+0.0))*(1+Вводные!$B$15)^8*(1+Вводные!$B$19))*(1-Вводные!$B$22-Вводные!$B$27)+(Модель!L17+Модель!L18+Модель!L19+Модель!L21))-MAX(0,((Вводные!$B$8*365*MIN((Вводные!$B$17+-0.1),Вводные!$B$16+((Вводные!$B$17+-0.1)-Вводные!$B$16)*MIN(1,8/Вводные!$B$18))*(Вводные!$B$14*(1+0.0))*(1+Вводные!$B$15)^8*(1+Вводные!$B$19))*(1-Вводные!$B$22-Вводные!$B$27)+(Модель!L17+Модель!L18+Модель!L19+Модель!L21))+Модель!L32+Модель!L29)*Вводные!$B$39+((Вводные!$B$8*365*MIN((Вводные!$B$17+-0.1),Вводные!$B$16+((Вводные!$B$17+-0.1)-Вводные!$B$16)*MIN(1,8/Вводные!$B$18))*(Вводные!$B$14*(1+0.0))*(1+Вводные!$B$15)^8*(1+Вводные!$B$19))*(1-Вводные!$B$22-Вводные!$B$27)+(Модель!L17+Модель!L18+Модель!L19+Модель!L21))*Вводные!$B$40 | M8: =SUMPRODUCT(B8:L8,Модель!$B$42:$L$42) | N8: =IFERROR(IRR(B8:L8),"—")
A9: Загрузка -10% · тариф +5% | B9: =Модель!B7 | C9: =Модель!C7 | D9: =((Вводные!$B$8*365*MIN((Вводные!$B$17+-0.1),Вводные!$B$16+((Вводные!$B$17+-0.1)-Вводные!$B$16)*MIN(1,0/Вводные!$B$18))*(Вводные!$B$14*(1+0.05))*(1+Вводные!$B$15)^0*(1+Вводные!$B$19))*(1-Вводные!$B$22-Вводные!$B$27)+(Модель!D17+Модель!D18+Модель!D19+Модель!D21))-MAX(0,((Вводные!$B$8*365*MIN((Вводные!$B$17+-0.1),Вводные!$B$16+((Вводные!$B$17+-0.1)-Вводные!$B$16)*MIN(1,0/Вводные!$B$18))*(Вводные!$B$14*(1+0.05))*(1+Вводные!$B$15)^0*(1+Вводные!$B$19))*(1-Вводные!$B$22-Вводные!$B$27)+(Модель!D17+Модель!D18+Модель!D19+Модель!D21))+Модель!D32+Модель!D29)*Вводные!$B$39 | E9: =((Вводные!$B$8*365*MIN((Вводные!$B$17+-0.1),Вводные!$B$16+((Вводные!$B$17+-0.1)-Вводные!$B$16)*MIN(1,1/Вводные!$B$18))*(Вводные!$B$14*(1+0.05))*(1+Вводные!$B$15)^1*(1+Вводные!$B$19))*(1-Вводные!$B$22-Вводные!$B$27)+(Модель!E17+Модель!E18+Модель!E19+Модель!E21))-MAX(0,((Вводные!$B$8*365*MIN((Вводные!$B$17+-0.1),Вводные!$B$16+((Вводные!$B$17+-0.1)-Вводные!$B$16)*MIN(1,1/Вводные!$B$18))*(Вводные!$B$14*(1+0.05))*(1+Вводные!$B$15)^1*(1+Вводные!$B$19))*(1-Вводные!$B$22-Вводные!$B$27)+(Модель!E17+Модель!E18+Модель!E19+Модель!E21))+Модель!E32+Модель!E29)*Вводные!$B$39 | F9: =((Вводные!$B$8*365*MIN((Вводные!$B$17+-0.1),Вводные!$B$16+((Вводные!$B$17+-0.1)-Вводные!$B$16)*MIN(1,2/Вводные!$B$18))*(Вводные!$B$14*(1+0.05))*(1+Вводные!$B$15)^2*(1+Вводные!$B$19))*(1-Вводные!$B$22-Вводные!$B$27)+(Модель!F17+Модель!F18+Модель!F19+Модель!F21))-MAX(0,((Вводные!$B$8*365*MIN((Вводные!$B$17+-0.1),Вводные!$B$16+((Вводные!$B$17+-0.1)-Вводные!$B$16)*MIN(1,2/Вводные!$B$18))*(Вводные!$B$14*(1+0.05))*(1+Вводные!$B$15)^2*(1+Вводные!$B$19))*(1-Вводные!$B$22-Вводные!$B$27)+(Модель!F17+Модель!F18+Модель!F19+Модель!F21))+Модель!F32+Модель!F29)*Вводные!$B$39 | G9: =((Вводные!$B$8*365*MIN((Вводные!$B$17+-0.1),Вводные!$B$16+((Вводные!$B$17+-0.1)-Вводные!$B$16)*MIN(1,3/Вводные!$B$18))*(Вводные!$B$14*(1+0.05))*(1+Вводные!$B$15)^3*(1+Вводные!$B$19))*(1-Вводные!$B$22-Вводные!$B$27)+(Модель!G17+Модель!G18+Модель!G19+Модель!G21))-MAX(0,((Вводные!$B$8*365*MIN((Вводные!$B$17+-0.1),Вводные!$B$16+((Вводные!$B$17+-0.1)-Вводные!$B$16)*MIN(1,3/Вводные!$B$18))*(Вводные!$B$14*(1+0.05))*(1+Вводные!$B$15)^3*(1+Вводные!$B$19))*(1-Вводные!$B$22-Вводные!$B$27)+(Модель!G17+Модель!G18+Модель!G19+Модель!G21))+Модель!G32+Модель!G29)*Вводные!$B$39 | H9: =((Вводные!$B$8*365*MIN((Вводные!$B$17+-0.1),Вводные!$B$16+((Вводные!$B$17+-0.1)-Вводные!$B$16)*MIN(1,4/Вводные!$B$18))*(Вводные!$B$14*(1+0.05))*(1+Вводные!$B$15)^4*(1+Вводные!$B$19))*(1-Вводные!$B$22-Вводные!$B$27)+(Модель!H17+Модель!H18+Модель!H19+Модель!H21))-MAX(0,((Вводные!$B$8*365*MIN((Вводные!$B$17+-0.1),Вводные!$B$16+((Вводные!$B$17+-0.1)-Вводные!$B$16)*MIN(1,4/Вводные!$B$18))*(Вводные!$B$14*(1+0.05))*(1+Вводные!$B$15)^4*(1+Вводные!$B$19))*(1-Вводные!$B$22-Вводные!$B$27)+(Модель!H17+Модель!H18+Модель!H19+Модель!H21))+Модель!H32+Модель!H29)*Вводные!$B$39 | I9: =((Вводные!$B$8*365*MIN((Вводные!$B$17+-0.1),Вводные!$B$16+((Вводные!$B$17+-0.1)-Вводные!$B$16)*MIN(1,5/Вводные!$B$18))*(Вводные!$B$14*(1+0.05))*(1+Вводные!$B$15)^5*(1+Вводные!$B$19))*(1-Вводные!$B$22-Вводные!$B$27)+(Модель!I17+Модель!I18+Модель!I19+Модель!I21))-MAX(0,((Вводные!$B$8*365*MIN((Вводные!$B$17+-0.1),Вводные!$B$16+((Вводные!$B$17+-0.1)-Вводные!$B$16)*MIN(1,5/Вводные!$B$18))*(Вводные!$B$14*(1+0.05))*(1+Вводные!$B$15)^5*(1+Вводные!$B$19))*(1-Вводные!$B$22-Вводные!$B$27)+(Модель!I17+Модель!I18+Модель!I19+Модель!I21))+Модель!I32+Модель!I29)*Вводные!$B$39 | J9: =((Вводные!$B$8*365*MIN((Вводные!$B$17+-0.1),Вводные!$B$16+((Вводные!$B$17+-0.1)-Вводные!$B$16)*MIN(1,6/Вводные!$B$18))*(Вводные!$B$14*(1+0.05))*(1+Вводные!$B$15)^6*(1+Вводные!$B$19))*(1-Вводные!$B$22-Вводные!$B$27)+(Модель!J17+Модель!J18+Модель!J19+Модель!J21))-MAX(0,((Вводные!$B$8*365*MIN((Вводные!$B$17+-0.1),Вводные!$B$16+((Вводные!$B$17+-0.1)-Вводные!$B$16)*MIN(1,6/Вводные!$B$18))*(Вводные!$B$14*(1+0.05))*(1+Вводные!$B$15)^6*(1+Вводные!$B$19))*(1-Вводные!$B$22-Вводные!$B$27)+(Модель!J17+Модель!J18+Модель!J19+Модель!J21))+Модель!J32+Модель!J29)*Вводные!$B$39 | K9: =((Вводные!$B$8*365*MIN((Вводные!$B$17+-0.1),Вводные!$B$16+((Вводные!$B$17+-0.1)-Вводные!$B$16)*MIN(1,7/Вводные!$B$18))*(Вводные!$B$14*(1+0.05))*(1+Вводные!$B$15)^7*(1+Вводные!$B$19))*(1-Вводные!$B$22-Вводные!$B$27)+(Модель!K17+Модель!K18+Модель!K19+Модель!K21))-MAX(0,((Вводные!$B$8*365*MIN((Вводные!$B$17+-0.1),Вводные!$B$16+((Вводные!$B$17+-0.1)-Вводные!$B$16)*MIN(1,7/Вводные!$B$18))*(Вводные!$B$14*(1+0.05))*(1+Вводные!$B$15)^7*(1+Вводные!$B$19))*(1-Вводные!$B$22-Вводные!$B$27)+(Модель!K17+Модель!K18+Модель!K19+Модель!K21))+Модель!K32+Модель!K29)*Вводные!$B$39 | L9: =((Вводные!$B$8*365*MIN((Вводные!$B$17+-0.1),Вводные!$B$16+((Вводные!$B$17+-0.1)-Вводные!$B$16)*MIN(1,8/Вводные!$B$18))*(Вводные!$B$14*(1+0.05))*(1+Вводные!$B$15)^8*(1+Вводные!$B$19))*(1-Вводные!$B$22-Вводные!$B$27)+(Модель!L17+Модель!L18+Модель!L19+Модель!L21))-MAX(0,((Вводные!$B$8*365*MIN((Вводные!$B$17+-0.1),Вводные!$B$16+((Вводные!$B$17+-0.1)-Вводные!$B$16)*MIN(1,8/Вводные!$B$18))*(Вводные!$B$14*(1+0.05))*(1+Вводные!$B$15)^8*(1+Вводные!$B$19))*(1-Вводные!$B$22-Вводные!$B$27)+(Модель!L17+Модель!L18+Модель!L19+Модель!L21))+Модель!L32+Модель!L29)*Вводные!$B$39+((Вводные!$B$8*365*MIN((Вводные!$B$17+-0.1),Вводные!$B$16+((Вводные!$B$17+-0.1)-Вводные!$B$16)*MIN(1,8/Вводные!$B$18))*(Вводные!$B$14*(1+0.05))*(1+Вводные!$B$15)^8*(1+Вводные!$B$19))*(1-Вводные!$B$22-Вводные!$B$27)+(Модель!L17+Модель!L18+Модель!L19+Модель!L21))*Вводные!$B$40 | M9: =SUMPRODUCT(B9:L9,Модель!$B$42:$L$42) | N9: =IFERROR(IRR(B9:L9),"—")
A10: Загрузка -10% · тариф +10% | B10: =Модель!B7 | C10: =Модель!C7 | D10: =((Вводные!$B$8*365*MIN((Вводные!$B$17+-0.1),Вводные!$B$16+((Вводные!$B$17+-0.1)-Вводные!$B$16)*MIN(1,0/Вводные!$B$18))*(Вводные!$B$14*(1+0.1))*(1+Вводные!$B$15)^0*(1+Вводные!$B$19))*(1-Вводные!$B$22-Вводные!$B$27)+(Модель!D17+Модель!D18+Модель!D19+Модель!D21))-MAX(0,((Вводные!$B$8*365*MIN((Вводные!$B$17+-0.1),Вводные!$B$16+((Вводные!$B$17+-0.1)-Вводные!$B$16)*MIN(1,0/Вводные!$B$18))*(Вводные!$B$14*(1+0.1))*(1+Вводные!$B$15)^0*(1+Вводные!$B$19))*(1-Вводные!$B$22-Вводные!$B$27)+(Модель!D17+Модель!D18+Модель!D19+Модель!D21))+Модель!D32+Модель!D29)*Вводные!$B$39 | E10: =((Вводные!$B$8*365*MIN((Вводные!$B$17+-0.1),Вводные!$B$16+((Вводные!$B$17+-0.1)-Вводные!$B$16)*MIN(1,1/Вводные!$B$18))*(Вводные!$B$14*(1+0.1))*(1+Вводные!$B$15)^1*(1+Вводные!$B$19))*(1-Вводные!$B$22-Вводные!$B$27)+(Модель!E17+Модель!E18+Модель!E19+Модель!E21))-MAX(0,((Вводные!$B$8*365*MIN((Вводные!$B$17+-0.1),Вводные!$B$16+((Вводные!$B$17+-0.1)-Вводные!$B$16)*MIN(1,1/Вводные!$B$18))*(Вводные!$B$14*(1+0.1))*(1+Вводные!$B$15)^1*(1+Вводные!$B$19))*(1-Вводные!$B$22-Вводные!$B$27)+(Модель!E17+Модель!E18+Модель!E19+Модель!E21))+Модель!E32+Модель!E29)*Вводные!$B$39 | F10: =((Вводные!$B$8*365*MIN((Вводные!$B$17+-0.1),Вводные!$B$16+((Вводные!$B$17+-0.1)-Вводные!$B$16)*MIN(1,2/Вводные!$B$18))*(Вводные!$B$14*(1+0.1))*(1+Вводные!$B$15)^2*(1+Вводные!$B$19))*(1-Вводные!$B$22-Вводные!$B$27)+(Модель!F17+Модель!F18+Модель!F19+Модель!F21))-MAX(0,((Вводные!$B$8*365*MIN((Вводные!$B$17+-0.1),Вводные!$B$16+((Вводные!$B$17+-0.1)-Вводные!$B$16)*MIN(1,2/Вводные!$B$18))*(Вводные!$B$14*(1+0.1))*(1+Вводные!$B$15)^2*(1+Вводные!$B$19))*(1-Вводные!$B$22-Вводные!$B$27)+(Модель!F17+Модель!F18+Модель!F19+Модель!F21))+Модель!F32+Модель!F29)*Вводные!$B$39 | G10: =((Вводные!$B$8*365*MIN((Вводные!$B$17+-0.1),Вводные!$B$16+((Вводные!$B$17+-0.1)-Вводные!$B$16)*MIN(1,3/Вводные!$B$18))*(Вводные!$B$14*(1+0.1))*(1+Вводные!$B$15)^3*(1+Вводные!$B$19))*(1-Вводные!$B$22-Вводные!$B$27)+(Модель!G17+Модель!G18+Модель!G19+Модель!G21))-MAX(0,((Вводные!$B$8*365*MIN((Вводные!$B$17+-0.1),Вводные!$B$16+((Вводные!$B$17+-0.1)-Вводные!$B$16)*MIN(1,3/Вводные!$B$18))*(Вводные!$B$14*(1+0.1))*(1+Вводные!$B$15)^3*(1+Вводные!$B$19))*(1-Вводные!$B$22-Вводные!$B$27)+(Модель!G17+Модель!G18+Модель!G19+Модель!G21))+Модель!G32+Модель!G29)*Вводные!$B$39 | H10: =((Вводные!$B$8*365*MIN((Вводные!$B$17+-0.1),Вводные!$B$16+((Вводные!$B$17+-0.1)-Вводные!$B$16)*MIN(1,4/Вводные!$B$18))*(Вводные!$B$14*(1+0.1))*(1+Вводные!$B$15)^4*(1+Вводные!$B$19))*(1-Вводные!$B$22-Вводные!$B$27)+(Модель!H17+Модель!H18+Модель!H19+Модель!H21))-MAX(0,((Вводные!$B$8*365*MIN((Вводные!$B$17+-0.1),Вводные!$B$16+((Вводные!$B$17+-0.1)-Вводные!$B$16)*MIN(1,4/Вводные!$B$18))*(Вводные!$B$14*(1+0.1))*(1+Вводные!$B$15)^4*(1+Вводные!$B$19))*(1-Вводные!$B$22-Вводные!$B$27)+(Модель!H17+Модель!H18+Модель!H19+Модель!H21))+Модель!H32+Модель!H29)*Вводные!$B$39 | I10: =((Вводные!$B$8*365*MIN((Вводные!$B$17+-0.1),Вводные!$B$16+((Вводные!$B$17+-0.1)-Вводные!$B$16)*MIN(1,5/Вводные!$B$18))*(Вводные!$B$14*(1+0.1))*(1+Вводные!$B$15)^5*(1+Вводные!$B$19))*(1-Вводные!$B$22-Вводные!$B$27)+(Модель!I17+Модель!I18+Модель!I19+Модель!I21))-MAX(0,((Вводные!$B$8*365*MIN((Вводные!$B$17+-0.1),Вводные!$B$16+((Вводные!$B$17+-0.1)-Вводные!$B$16)*MIN(1,5/Вводные!$B$18))*(Вводные!$B$14*(1+0.1))*(1+Вводные!$B$15)^5*(1+Вводные!$B$19))*(1-Вводные!$B$22-Вводные!$B$27)+(Модель!I17+Модель!I18+Модель!I19+Модель!I21))+Модель!I32+Модель!I29)*Вводные!$B$39 | J10: =((Вводные!$B$8*365*MIN((Вводные!$B$17+-0.1),Вводные!$B$16+((Вводные!$B$17+-0.1)-Вводные!$B$16)*MIN(1,6/Вводные!$B$18))*(Вводные!$B$14*(1+0.1))*(1+Вводные!$B$15)^6*(1+Вводные!$B$19))*(1-Вводные!$B$22-Вводные!$B$27)+(Модель!J17+Модель!J18+Модель!J19+Модель!J21))-MAX(0,((Вводные!$B$8*365*MIN((Вводные!$B$17+-0.1),Вводные!$B$16+((Вводные!$B$17+-0.1)-Вводные!$B$16)*MIN(1,6/Вводные!$B$18))*(Вводные!$B$14*(1+0.1))*(1+Вводные!$B$15)^6*(1+Вводные!$B$19))*(1-Вводные!$B$22-Вводные!$B$27)+(Модель!J17+Модель!J18+Модель!J19+Модель!J21))+Модель!J32+Модель!J29)*Вводные!$B$39 | K10: =((Вводные!$B$8*365*MIN((Вводные!$B$17+-0.1),Вводные!$B$16+((Вводные!$B$17+-0.1)-Вводные!$B$16)*MIN(1,7/Вводные!$B$18))*(Вводные!$B$14*(1+0.1))*(1+Вводные!$B$15)^7*(1+Вводные!$B$19))*(1-Вводные!$B$22-Вводные!$B$27)+(Модель!K17+Модель!K18+Модель!K19+Модель!K21))-MAX(0,((Вводные!$B$8*365*MIN((Вводные!$B$17+-0.1),Вводные!$B$16+((Вводные!$B$17+-0.1)-Вводные!$B$16)*MIN(1,7/Вводные!$B$18))*(Вводные!$B$14*(1+0.1))*(1+Вводные!$B$15)^7*(1+Вводные!$B$19))*(1-Вводные!$B$22-Вводные!$B$27)+(Модель!K17+Модель!K18+Модель!K19+Модель!K21))+Модель!K32+Модель!K29)*Вводные!$B$39 | L10: =((Вводные!$B$8*365*MIN((Вводные!$B$17+-0.1),Вводные!$B$16+((Вводные!$B$17+-0.1)-Вводные!$B$16)*MIN(1,8/Вводные!$B$18))*(Вводные!$B$14*(1+0.1))*(1+Вводные!$B$15)^8*(1+Вводные!$B$19))*(1-Вводные!$B$22-Вводные!$B$27)+(Модель!L17+Модель!L18+Модель!L19+Модель!L21))-MAX(0,((Вводные!$B$8*365*MIN((Вводные!$B$17+-0.1),Вводные!$B$16+((Вводные!$B$17+-0.1)-Вводные!$B$16)*MIN(1,8/Вводные!$B$18))*(Вводные!$B$14*(1+0.1))*(1+Вводные!$B$15)^8*(1+Вводные!$B$19))*(1-Вводные!$B$22-Вводные!$B$27)+(Модель!L17+Модель!L18+Модель!L19+Модель!L21))+Модель!L32+Модель!L29)*Вводные!$B$39+((Вводные!$B$8*365*MIN((Вводные!$B$17+-0.1),Вводные!$B$16+((Вводные!$B$17+-0.1)-Вводные!$B$16)*MIN(1,8/Вводные!$B$18))*(Вводные!$B$14*(1+0.1))*(1+Вводные!$B$15)^8*(1+Вводные!$B$19))*(1-Вводные!$B$22-Вводные!$B$27)+(Модель!L17+Модель!L18+Модель!L19+Модель!L21))*Вводные!$B$40 | M10: =SUMPRODUCT(B10:L10,Модель!$B$42:$L$42) | N10: =IFERROR(IRR(B10:L10),"—")
A11: Загрузка -5% · тариф -10% | B11: =Модель!B7 | C11: =Модель!C7 | D11: =((Вводные!$B$8*365*MIN((Вводные!$B$17+-0.05),Вводные!$B$16+((Вводные!$B$17+-0.05)-Вводные!$B$16)*MIN(1,0/Вводные!$B$18))*(Вводные!$B$14*(1+-0.1))*(1+Вводные!$B$15)^0*(1+Вводные!$B$19))*(1-Вводные!$B$22-Вводные!$B$27)+(Модель!D17+Модель!D18+Модель!D19+Модель!D21))-MAX(0,((Вводные!$B$8*365*MIN((Вводные!$B$17+-0.05),Вводные!$B$16+((Вводные!$B$17+-0.05)-Вводные!$B$16)*MIN(1,0/Вводные!$B$18))*(Вводные!$B$14*(1+-0.1))*(1+Вводные!$B$15)^0*(1+Вводные!$B$19))*(1-Вводные!$B$22-Вводные!$B$27)+(Модель!D17+Модель!D18+Модель!D19+Модель!D21))+Модель!D32+Модель!D29)*Вводные!$B$39 | E11: =((Вводные!$B$8*365*MIN((Вводные!$B$17+-0.05),Вводные!$B$16+((Вводные!$B$17+-0.05)-Вводные!$B$16)*MIN(1,1/Вводные!$B$18))*(Вводные!$B$14*(1+-0.1))*(1+Вводные!$B$15)^1*(1+Вводные!$B$19))*(1-Вводные!$B$22-Вводные!$B$27)+(Модель!E17+Модель!E18+Модель!E19+Модель!E21))-MAX(0,((Вводные!$B$8*365*MIN((Вводные!$B$17+-0.05),Вводные!$B$16+((Вводные!$B$17+-0.05)-Вводные!$B$16)*MIN(1,1/Вводные!$B$18))*(Вводные!$B$14*(1+-0.1))*(1+Вводные!$B$15)^1*(1+Вводные!$B$19))*(1-Вводные!$B$22-Вводные!$B$27)+(Модель!E17+Модель!E18+Модель!E19+Модель!E21))+Модель!E32+Модель!E29)*Вводные!$B$39 | F11: =((Вводные!$B$8*365*MIN((Вводные!$B$17+-0.05),Вводные!$B$16+((Вводные!$B$17+-0.05)-Вводные!$B$16)*MIN(1,2/Вводные!$B$18))*(Вводные!$B$14*(1+-0.1))*(1+Вводные!$B$15)^2*(1+Вводные!$B$19))*(1-Вводные!$B$22-Вводные!$B$27)+(Модель!F17+Модель!F18+Модель!F19+Модель!F21))-MAX(0,((Вводные!$B$8*365*MIN((Вводные!$B$17+-0.05),Вводные!$B$16+((Вводные!$B$17+-0.05)-Вводные!$B$16)*MIN(1,2/Вводные!$B$18))*(Вводные!$B$14*(1+-0.1))*(1+Вводные!$B$15)^2*(1+Вводные!$B$19))*(1-Вводные!$B$22-Вводные!$B$27)+(Модель!F17+Модель!F18+Модель!F19+Модель!F21))+Модель!F32+Модель!F29)*Вводные!$B$39 | G11: =((Вводные!$B$8*365*MIN((Вводные!$B$17+-0.05),Вводные!$B$16+((Вводные!$B$17+-0.05)-Вводные!$B$16)*MIN(1,3/Вводные!$B$18))*(Вводные!$B$14*(1+-0.1))*(1+Вводные!$B$15)^3*(1+Вводные!$B$19))*(1-Вводные!$B$22-Вводные!$B$27)+(Модель!G17+Модель!G18+Модель!G19+Модель!G21))-MAX(0,((Вводные!$B$8*365*MIN((Вводные!$B$17+-0.05),Вводные!$B$16+((Вводные!$B$17+-0.05)-Вводные!$B$16)*MIN(1,3/Вводные!$B$18))*(Вводные!$B$14*(1+-0.1))*(1+Вводные!$B$15)^3*(1+Вводные!$B$19))*(1-Вводные!$B$22-Вводные!$B$27)+(Модель!G17+Модель!G18+Модель!G19+Модель!G21))+Модель!G32+Модель!G29)*Вводные!$B$39 | H11: =((Вводные!$B$8*365*MIN((Вводные!$B$17+-0.05),Вводные!$B$16+((Вводные!$B$17+-0.05)-Вводные!$B$16)*MIN(1,4/Вводные!$B$18))*(Вводные!$B$14*(1+-0.1))*(1+Вводные!$B$15)^4*(1+Вводные!$B$19))*(1-Вводные!$B$22-Вводные!$B$27)+(Модель!H17+Модель!H18+Модель!H19+Модель!H21))-MAX(0,((Вводные!$B$8*365*MIN((Вводные!$B$17+-0.05),Вводные!$B$16+((Вводные!$B$17+-0.05)-Вводные!$B$16)*MIN(1,4/Вводные!$B$18))*(Вводные!$B$14*(1+-0.1))*(1+Вводные!$B$15)^4*(1+Вводные!$B$19))*(1-Вводные!$B$22-Вводные!$B$27)+(Модель!H17+Модель!H18+Модель!H19+Модель!H21))+Модель!H32+Модель!H29)*Вводные!$B$39 | I11: =((Вводные!$B$8*365*MIN((Вводные!$B$17+-0.05),Вводные!$B$16+((Вводные!$B$17+-0.05)-Вводные!$B$16)*MIN(1,5/Вводные!$B$18))*(Вводные!$B$14*(1+-0.1))*(1+Вводные!$B$15)^5*(1+Вводные!$B$19))*(1-Вводные!$B$22-Вводные!$B$27)+(Модель!I17+Модель!I18+Модель!I19+Модель!I21))-MAX(0,((Вводные!$B$8*365*MIN((Вводные!$B$17+-0.05),Вводные!$B$16+((Вводные!$B$17+-0.05)-Вводные!$B$16)*MIN(1,5/Вводные!$B$18))*(Вводные!$B$14*(1+-0.1))*(1+Вводные!$B$15)^5*(1+Вводные!$B$19))*(1-Вводные!$B$22-Вводные!$B$27)+(Модель!I17+Модель!I18+Модель!I19+Модель!I21))+Модель!I32+Модель!I29)*Вводные!$B$39 | J11: =((Вводные!$B$8*365*MIN((Вводные!$B$17+-0.05),Вводные!$B$16+((Вводные!$B$17+-0.05)-Вводные!$B$16)*MIN(1,6/Вводные!$B$18))*(Вводные!$B$14*(1+-0.1))*(1+Вводные!$B$15)^6*(1+Вводные!$B$19))*(1-Вводные!$B$22-Вводные!$B$27)+(Модель!J17+Модель!J18+Модель!J19+Модель!J21))-MAX(0,((Вводные!$B$8*365*MIN((Вводные!$B$17+-0.05),Вводные!$B$16+((Вводные!$B$17+-0.05)-Вводные!$B$16)*MIN(1,6/Вводные!$B$18))*(Вводные!$B$14*(1+-0.1))*(1+Вводные!$B$15)^6*(1+Вводные!$B$19))*(1-Вводные!$B$22-Вводные!$B$27)+(Модель!J17+Модель!J18+Модель!J19+Модель!J21))+Модель!J32+Модель!J29)*Вводные!$B$39 | K11: =((Вводные!$B$8*365*MIN((Вводные!$B$17+-0.05),Вводные!$B$16+((Вводные!$B$17+-0.05)-Вводные!$B$16)*MIN(1,7/Вводные!$B$18))*(Вводные!$B$14*(1+-0.1))*(1+Вводные!$B$15)^7*(1+Вводные!$B$19))*(1-Вводные!$B$22-Вводные!$B$27)+(Модель!K17+Модель!K18+Модель!K19+Модель!K21))-MAX(0,((Вводные!$B$8*365*MIN((Вводные!$B$17+-0.05),Вводные!$B$16+((Вводные!$B$17+-0.05)-Вводные!$B$16)*MIN(1,7/Вводные!$B$18))*(Вводные!$B$14*(1+-0.1))*(1+Вводные!$B$15)^7*(1+Вводные!$B$19))*(1-Вводные!$B$22-Вводные!$B$27)+(Модель!K17+Модель!K18+Модель!K19+Модель!K21))+Модель!K32+Модель!K29)*Вводные!$B$39 | L11: =((Вводные!$B$8*365*MIN((Вводные!$B$17+-0.05),Вводные!$B$16+((Вводные!$B$17+-0.05)-Вводные!$B$16)*MIN(1,8/Вводные!$B$18))*(Вводные!$B$14*(1+-0.1))*(1+Вводные!$B$15)^8*(1+Вводные!$B$19))*(1-Вводные!$B$22-Вводные!$B$27)+(Модель!L17+Модель!L18+Модель!L19+Модель!L21))-MAX(0,((Вводные!$B$8*365*MIN((Вводные!$B$17+-0.05),Вводные!$B$16+((Вводные!$B$17+-0.05)-Вводные!$B$16)*MIN(1,8/Вводные!$B$18))*(Вводные!$B$14*(1+-0.1))*(1+Вводные!$B$15)^8*(1+Вводные!$B$19))*(1-Вводные!$B$22-Вводные!$B$27)+(Модель!L17+Модель!L18+Модель!L19+Модель!L21))+Модель!L32+Модель!L29)*Вводные!$B$39+((Вводные!$B$8*365*MIN((Вводные!$B$17+-0.05),Вводные!$B$16+((Вводные!$B$17+-0.05)-Вводные!$B$16)*MIN(1,8/Вводные!$B$18))*(Вводные!$B$14*(1+-0.1))*(1+Вводные!$B$15)^8*(1+Вводные!$B$19))*(1-Вводные!$B$22-Вводные!$B$27)+(Модель!L17+Модель!L18+Модель!L19+Модель!L21))*Вводные!$B$40 | M11: =SUMPRODUCT(B11:L11,Модель!$B$42:$L$42) | N11: =IFERROR(IRR(B11:L11),"—")
A12: Загрузка -5% · тариф -5% | B12: =Модель!B7 | C12: =Модель!C7 | D12: =((Вводные!$B$8*365*MIN((Вводные!$B$17+-0.05),Вводные!$B$16+((Вводные!$B$17+-0.05)-Вводные!$B$16)*MIN(1,0/Вводные!$B$18))*(Вводные!$B$14*(1+-0.05))*(1+Вводные!$B$15)^0*(1+Вводные!$B$19))*(1-Вводные!$B$22-Вводные!$B$27)+(Модель!D17+Модель!D18+Модель!D19+Модель!D21))-MAX(0,((Вводные!$B$8*365*MIN((Вводные!$B$17+-0.05),Вводные!$B$16+((Вводные!$B$17+-0.05)-Вводные!$B$16)*MIN(1,0/Вводные!$B$18))*(Вводные!$B$14*(1+-0.05))*(1+Вводные!$B$15)^0*(1+Вводные!$B$19))*(1-Вводные!$B$22-Вводные!$B$27)+(Модель!D17+Модель!D18+Модель!D19+Модель!D21))+Модель!D32+Модель!D29)*Вводные!$B$39 | E12: =((Вводные!$B$8*365*MIN((Вводные!$B$17+-0.05),Вводные!$B$16+((Вводные!$B$17+-0.05)-Вводные!$B$16)*MIN(1,1/Вводные!$B$18))*(Вводные!$B$14*(1+-0.05))*(1+Вводные!$B$15)^1*(1+Вводные!$B$19))*(1-Вводные!$B$22-Вводные!$B$27)+(Модель!E17+Модель!E18+Модель!E19+Модель!E21))-MAX(0,((Вводные!$B$8*365*MIN((Вводные!$B$17+-0.05),Вводные!$B$16+((Вводные!$B$17+-0.05)-Вводные!$B$16)*MIN(1,1/Вводные!$B$18))*(Вводные!$B$14*(1+-0.05))*(1+Вводные!$B$15)^1*(1+Вводные!$B$19))*(1-Вводные!$B$22-Вводные!$B$27)+(Модель!E17+Модель!E18+Модель!E19+Модель!E21))+Модель!E32+Модель!E29)*Вводные!$B$39 | F12: =((Вводные!$B$8*365*MIN((Вводные!$B$17+-0.05),Вводные!$B$16+((Вводные!$B$17+-0.05)-Вводные!$B$16)*MIN(1,2/Вводные!$B$18))*(Вводные!$B$14*(1+-0.05))*(1+Вводные!$B$15)^2*(1+Вводные!$B$19))*(1-Вводные!$B$22-Вводные!$B$27)+(Модель!F17+Модель!F18+Модель!F19+Модель!F21))-MAX(0,((Вводные!$B$8*365*MIN((Вводные!$B$17+-0.05),Вводные!$B$16+((Вводные!$B$17+-0.05)-Вводные!$B$16)*MIN(1,2/Вводные!$B$18))*(Вводные!$B$14*(1+-0.05))*(1+Вводные!$B$15)^2*(1+Вводные!$B$19))*(1-Вводные!$B$22-Вводные!$B$27)+(Модель!F17+Модель!F18+Модель!F19+Модель!F21))+Модель!F32+Модель!F29)*Вводные!$B$39 | G12: =((Вводные!$B$8*365*MIN((Вводные!$B$17+-0.05),Вводные!$B$16+((Вводные!$B$17+-0.05)-Вводные!$B$16)*MIN(1,3/Вводные!$B$18))*(Вводные!$B$14*(1+-0.05))*(1+Вводные!$B$15)^3*(1+Вводные!$B$19))*(1-Вводные!$B$22-Вводные!$B$27)+(Модель!G17+Модель!G18+Модель!G19+Модель!G21))-MAX(0,((Вводные!$B$8*365*MIN((Вводные!$B$17+-0.05),Вводные!$B$16+((Вводные!$B$17+-0.05)-Вводные!$B$16)*MIN(1,3/Вводные!$B$18))*(Вводные!$B$14*(1+-0.05))*(1+Вводные!$B$15)^3*(1+Вводные!$B$19))*(1-Вводные!$B$22-Вводные!$B$27)+(Модель!G17+Модель!G18+Модель!G19+Модель!G21))+Модель!G32+Модель!G29)*Вводные!$B$39 | H12: =((Вводные!$B$8*365*MIN((Вводные!$B$17+-0.05),Вводные!$B$16+((Вводные!$B$17+-0.05)-Вводные!$B$16)*MIN(1,4/Вводные!$B$18))*(Вводные!$B$14*(1+-0.05))*(1+Вводные!$B$15)^4*(1+Вводные!$B$19))*(1-Вводные!$B$22-Вводные!$B$27)+(Модель!H17+Модель!H18+Модель!H19+Модель!H21))-MAX(0,((Вводные!$B$8*365*MIN((Вводные!$B$17+-0.05),Вводные!$B$16+((Вводные!$B$17+-0.05)-Вводные!$B$16)*MIN(1,4/Вводные!$B$18))*(Вводные!$B$14*(1+-0.05))*(1+Вводные!$B$15)^4*(1+Вводные!$B$19))*(1-Вводные!$B$22-Вводные!$B$27)+(Модель!H17+Модель!H18+Модель!H19+Модель!H21))+Модель!H32+Модель!H29)*Вводные!$B$39 | I12: =((Вводные!$B$8*365*MIN((Вводные!$B$17+-0.05),Вводные!$B$16+((Вводные!$B$17+-0.05)-Вводные!$B$16)*MIN(1,5/Вводные!$B$18))*(Вводные!$B$14*(1+-0.05))*(1+Вводные!$B$15)^5*(1+Вводные!$B$19))*(1-Вводные!$B$22-Вводные!$B$27)+(Модель!I17+Модель!I18+Модель!I19+Модель!I21))-MAX(0,((Вводные!$B$8*365*MIN((Вводные!$B$17+-0.05),Вводные!$B$16+((Вводные!$B$17+-0.05)-Вводные!$B$16)*MIN(1,5/Вводные!$B$18))*(Вводные!$B$14*(1+-0.05))*(1+Вводные!$B$15)^5*(1+Вводные!$B$19))*(1-Вводные!$B$22-Вводные!$B$27)+(Модель!I17+Модель!I18+Модель!I19+Модель!I21))+Модель!I32+Модель!I29)*Вводные!$B$39 | J12: =((Вводные!$B$8*365*MIN((Вводные!$B$17+-0.05),Вводные!$B$16+((Вводные!$B$17+-0.05)-Вводные!$B$16)*MIN(1,6/Вводные!$B$18))*(Вводные!$B$14*(1+-0.05))*(1+Вводные!$B$15)^6*(1+Вводные!$B$19))*(1-Вводные!$B$22-Вводные!$B$27)+(Модель!J17+Модель!J18+Модель!J19+Модель!J21))-MAX(0,((Вводные!$B$8*365*MIN((Вводные!$B$17+-0.05),Вводные!$B$16+((Вводные!$B$17+-0.05)-Вводные!$B$16)*MIN(1,6/Вводные!$B$18))*(Вводные!$B$14*(1+-0.05))*(1+Вводные!$B$15)^6*(1+Вводные!$B$19))*(1-Вводные!$B$22-Вводные!$B$27)+(Модель!J17+Модель!J18+Модель!J19+Модель!J21))+Модель!J32+Модель!J29)*Вводные!$B$39 | K12: =((Вводные!$B$8*365*MIN((Вводные!$B$17+-0.05),Вводные!$B$16+((Вводные!$B$17+-0.05)-Вводные!$B$16)*MIN(1,7/Вводные!$B$18))*(Вводные!$B$14*(1+-0.05))*(1+Вводные!$B$15)^7*(1+Вводные!$B$19))*(1-Вводные!$B$22-Вводные!$B$27)+(Модель!K17+Модель!K18+Модель!K19+Модель!K21))-MAX(0,((Вводные!$B$8*365*MIN((Вводные!$B$17+-0.05),Вводные!$B$16+((Вводные!$B$17+-0.05)-Вводные!$B$16)*MIN(1,7/Вводные!$B$18))*(Вводные!$B$14*(1+-0.05))*(1+Вводные!$B$15)^7*(1+Вводные!$B$19))*(1-Вводные!$B$22-Вводные!$B$27)+(Модель!K17+Модель!K18+Модель!K19+Модель!K21))+Модель!K32+Модель!K29)*Вводные!$B$39 | L12: =((Вводные!$B$8*365*MIN((Вводные!$B$17+-0.05),Вводные!$B$16+((Вводные!$B$17+-0.05)-Вводные!$B$16)*MIN(1,8/Вводные!$B$18))*(Вводные!$B$14*(1+-0.05))*(1+Вводные!$B$15)^8*(1+Вводные!$B$19))*(1-Вводные!$B$22-Вводные!$B$27)+(Модель!L17+Модель!L18+Модель!L19+Модель!L21))-MAX(0,((Вводные!$B$8*365*MIN((Вводные!$B$17+-0.05),Вводные!$B$16+((Вводные!$B$17+-0.05)-Вводные!$B$16)*MIN(1,8/Вводные!$B$18))*(Вводные!$B$14*(1+-0.05))*(1+Вводные!$B$15)^8*(1+Вводные!$B$19))*(1-Вводные!$B$22-Вводные!$B$27)+(Модель!L17+Модель!L18+Модель!L19+Модель!L21))+Модель!L32+Модель!L29)*Вводные!$B$39+((Вводные!$B$8*365*MIN((Вводные!$B$17+-0.05),Вводные!$B$16+((Вводные!$B$17+-0.05)-Вводные!$B$16)*MIN(1,8/Вводные!$B$18))*(Вводные!$B$14*(1+-0.05))*(1+Вводные!$B$15)^8*(1+Вводные!$B$19))*(1-Вводные!$B$22-Вводные!$B$27)+(Модель!L17+Модель!L18+Модель!L19+Модель!L21))*Вводные!$B$40 | M12: =SUMPRODUCT(B12:L12,Модель!$B$42:$L$42) | N12: =IFERROR(IRR(B12:L12),"—")
